Workbook

Sheet Targets Daily 2025
A1: Total PCS Generation (GWh) | B1: Total Meter Generation (GWh)
A2: =SUM(D:D)/1000 -> #REF! | B2: =SUM(E:E)/1000 -> #REF!
A3: Contractual Target (Lower) (GWh) | B3: Contractual Target (GWh)
A4: =B4/100*90 -> 68.5152 | B4: 76.128
A5: Lower Bound Pct Completion | B5: Contractual Target Pct Completion
A6: =B2/A4 -> #REF! | B6: =B2/B4 -> #REF!
A7: Shortfall to Contractual Lower (GWh) | B7: Shortfall to Contractual Target (GWh)
A8: =$A$4-$B$2 -> #REF! | B8: =$B$4-$B$2 -> #REF!
A9: Current Year | B9: Remaining Days in Year
A10: 2025 | B10: =DATEVALUE(_xlfn.CONCAT("31-Dec-",A10))-MAX(C:C) -> -981
A11: % on track Lower | B11: % on track Upper
A12: =(($B$2/(366-$B$10)) / ($A$8/$B$10))-1 -> #REF!
A13: Average Daily MWh to LowerBound | B13: Average Daily MWh to Contractual Target
A14: =A8*1000/B10 -> #REF! | B14: =B8*1000/B10 -> #REF!
C17: Date | D17: PCS Generation (MWh) | E17: Meter Generation (MWh)
C18: ='Summary (PV)'!A1290 -> 46914 | D18: =#REF!/1000 -> #REF! | E18: ='Summary (PV)'!#REF!/1000 -> #REF!
C19: ='Summary (PV)'!A1291 -> 46915 | D19: =#REF!/1000 -> #REF! | E19: ='Summary (PV)'!#REF!/1000 -> #REF!
C20: ='Summary (PV)'!A1292 -> 46916 | D20: =#REF!/1000 -> #REF! | E20: ='Summary (PV)'!#REF!/1000 -> #REF!
C21: ='Summary (PV)'!A1293 -> 46917 | D21: =#REF!/1000 -> #REF! | E21: ='Summary (PV)'!#REF!/1000 -> #REF!
C22: ='Summary (PV)'!A1294 -> 46918 | D22: =#REF!/1000 -> #REF! | E22: ='Summary (PV)'!#REF!/1000 -> #REF!
C23: ='Summary (PV)'!A1295 -> 46919 | D23: =#REF!/1000 -> #REF! | E23: ='Summary (PV)'!#REF!/1000 -> #REF!
C24: ='Summary (PV)'!A1296 -> 46920 | D24: =#REF!/1000 -> #REF! | E24: ='Summary (PV)'!#REF!/1000 -> #REF!
C25: ='Summary (PV)'!A1297 -> 46921 | D25: =#REF!/1000 -> #REF! | E25: ='Summary (PV)'!#REF!/1000 -> #REF!
C26: ='Summary (PV)'!A1298 -> 46922 | D26: =#REF!/1000 -> #REF! | E26: ='Summary (PV)'!#REF!/1000 -> #REF!
C27: ='Summary (PV)'!A1299 -> 46923 | D27: =#REF!/1000 -> #REF! | E27: ='Summary (PV)'!#REF!/1000 -> #REF!
C28: ='Summary (PV)'!A1300 -> 46924 | D28: =#REF!/1000 -> #REF! | E28: ='Summary (PV)'!#REF!/1000 -> #REF!
C29: ='Summary (PV)'!A1301 -> 46925 | D29: =#REF!/1000 -> #REF! | E29: ='Summary (PV)'!#REF!/1000 -> #REF!
... C107: ='Summary (PV)'!A1379 -> 47003 | D107: =#REF!/1000 -> #REF! | E107: ='Summary (PV)'!#REF!/1000 -> #REF!

Sheet Detail1
A1: Details for Sum of Average GHI - Months (Date): Jun, Years (Date): 2025
A3: Date | B3: Energy (kWh) | C3: GHI | D3: SY | E3: PR | F3: Availability | G3: OG1 | H3: OG2 | I3: OG3 | J3: OG4 | K3: OG5 | L3: Total Meter Generation (kWh) | M3: PAE Energy (kWh) | N3: Curtailed Energy (kWh) | O3: Corrected Meter Generation (kWh) | P3: STS1 | Q3: STS2 | R3: STS3 | S3: STS4 | T3: STS5 | U3: STS6 | V3: STS7 | W3: STS8 | X3: STS9 | Y3: STS10 | Z3: Total STS Generation (kWh) | AA3: Corrected STS Generation (kWh) | AB3: STS12 | AC3: STS22 | AD3: STS32 | AE3: STS42 | AF3: STS52 | AG3: STS62 | AH3: STS72 | AI3: STS82 | AJ3: STS92 | AK3: STS102 | AL3: MTR-STS Ratio (Mtr/Inv) | AM3: Daily Specific Yield | AN3: WS01 | AO3: WS02 | AP3: WS03 | AQ3: WS04 | AR3: WS05 | AS3: Average GHI | AT3: Plant Performance Ratio (PR) | AU3: Corrected Plant PR | AV3: System Availability (%) | AW3: PV Capacity (kWp) | AX3: AC Capacity | AY3: Special remarks (any event happened causing low Performance?)
A4: 45838 | B4: 236808 | C4: 4.14 | D4: 3.393558 | E4: 0.8197 | F4: 0.99 | G4: 42671 | H4: 42681 | I4: 0 | J4: 46974 | K4: 42738 | L4: 175064 | M4: 158399.33 | N4: 0 | O4: 175064 | P4: 13140 | Q4: 13110 | R4: 11550 | S4: 14230 | T4: 14880 | U4: 15380 | V4: 12910 | W4: 13040 | X4: 14760 | Y4: 13390 | Z4: 136390 | AA4: 136390 | AB4: 0.9782 | AC4: 0.9762 | AD4: 0.9674 | AE4: 0.9385 | AF4: 0.9815 | AG4: 1.0016 | AH4: 0.9702 | AI4: 0.9803 | AJ4: 0.961 | AK4: 1 | AL4: 0.77908651 | AM4: 2.4484476 | AN4: 1.92 | AO4: 1.99 | AP4: 2.03 | AQ4: 1.99 | AS4: 1.9825 | AT4: 0.9761 | AU4: 1.2350303 | AV4: 1 | AW4: 71500 | AX4: 56992 | AY4: - The measurement at Weather Station 5 (STS-2) is not normal. - Power limitation on Busbar 1 (STS1-STS5) due to considerations of the feeder line capacity.
A5: 45837 | B5: 236808 | C5: 4.14 | D5: 3.393558 | E5: 0.8197 | F5: 0.99 | G5: 55263 | H5: 55091 | I5: 0 | J5: 61985 | K5: 56054 | L5: 228393 | M5: 256854.83 | N5: 28461.83 | O5: 256854.83 | P5: 25580 | Q5: 25320 | R5: 21970 | S5: 26670 | T5: 27760 | U5: 30830 | V5: 25930 | W5: 25980 | X5: 29550 | Y5: 26260 | Z5: 265850 | AA5: 294311.83 | AB5: 0.7994 | AC5: 0.7913 | AD5: 0.7725 | AE5: 0.7383 | AF5: 0.775 | AG5: 0.8342 | AH5: 0.8098 | AI5: 0.8114 | AJ5: 0.7994 | AK5: 0.8201 | AL5: 1.1640024 | AM5: 3.5923752 | AN5: 4.62 | AO5: 4.7 | AP5: 4.98 | AQ5: 4.74 | AS5: 4.76 | AT5: 0.7951 | AU5: 0.75470068 | AV5: 1 | AW5: 71500 | AX5: 56992 | AY5: - The measurement at Weather Station 5 (STS-2) is not normal. - Power limitation on Busbar 1 (STS1-STS5) due to considerations of the feeder line capacity.
A6: 45836 | B6: 236808 | C6: 4.14 | D6: 3.393558 | E6: 0.8197 | F6: 0.99 | G6: 61685 | H6: 61577 | I6: 0 | J6: 70367 | K6: 63559 | L6: 257188 | M6: 264190.67 | N6: 7002.67 | O6: 264190.67 | P6: 23170 | Q6: 22560 | R6: 20130 | S6: 24230 | T6: 25970 | U6: 27970 | V6: 24220 | W6: 24080 | X6: 28040 | Y6: 24880 | Z6: 245250 | AA6: 252252.67 | AB6: 0.8669 | AC6: 0.8439 | AD6: 0.8472 | AE6: 0.8031 | AF6: 0.8352 | AG6: 0.8675 | AH6: 0.8673 | AI6: 0.8622 | AJ6: 0.8696 | AK6: 0.8908 | AL6: 0.95358259 | AM6: 3.6949744 | AN6: 4.03 | AO6: 4.08 | AP6: 4.23 | AQ6: 3.96 | AS6: 4.075 | AT6: 0.8554 | AU6: 0.90674219 | AV6: 1 | AW6: 71500 | AX6: 56992 | AY6: - The measurement at Weather Station 5 (STS-2) is not normal. - Power limitation on Busbar 1 (STS1-STS5) due to considerations of the feeder line capacity.
A7: 45835 | B7: 236808 | C7: 4.14 | D7: 3.393558 | E7: 0.8197 | F7: 0.99 | G7: 72264 | H7: 72018 | I7: 0 | J7: 81406 | K7: 74203 | L7: 299891 | M7: 309808.5 | N7: 9917.5 | O7: 309808.5 | P7: 30360 | Q7: 29860 | R7: 26020 | S7: 31740 | T7: 32320 | U7: 35630 | V7: 30200 | W7: 29930 | X7: 33560 | Y7: 30300 | Z7: 309920 | AA7: 319837.5 | AB7: 0.8282 | AC7: 0.8147 | AD7: 0.7988 | AE7: 0.767 | AF7: 0.8002 | AG7: 0.8681 | AH7: 0.8495 | AI7: 0.8419 | AJ7: 0.8177 | AK7: 0.8523 | AL7: 1.0334422 | AM7: 4.332986 | AN7: 5.13 | AO7: 5.3 | AP7: 5.59 | AQ7: 5.43 | AS7: 5.3625 | AT7: 0.8238 | AU7: 0.80801604 | AV7: 1 | AW7: 71500 | AX7: 56992 | AY7: - The measurement at Weather Station 5 (STS-2) is not normal. - Power limitation on Busbar 1 (STS1-STS5) due to considerations of the feeder line capacity.
A8: 45834 | B8: 236808 | C8: 4.14 | D8: 3.393558 | E8: 0.8197 | F8: 0.99 | G8: 75976 | H8: 75877 | I8: 0 | J8: 83405 | K8: 76258 | L8: 311516 | M8: 300419.17 | N8: 0 | O8: 311516 | P8: 28600 | Q8: 28630 | R8: 25350 | S8: 31190 | T8: 32410 | U8: 34260 | V8: 29430 | W8: 28780 | X8: 31540 | Y8: 29660 | Z8: 299850 | AA8: 299850 | AB8: 0.89 | AC8: 0.89 | AD8: 0.89 | AE8: 0.86 | AF8: 0.88 | AG8: 0.93 | AH8: 0.92 | AI8: 0.9 | AJ8: 0.85 | AK8: 0.92 | AL8: 0.96255088 | AM8: 4.3568671 | AN8: 4.61 | AO8: 4.83 | AP8: 4.93 | AQ8: 4.73 | AS8: 4.775 | AT8: 0.89 | AU8: 0.91243291 | AV8: 1 | AW8: 71500 | AX8: 56992 | AY8: -The measurement at Weather Station 3 (STS-6) and 5 (STS-2) is not normal. - Power limitation on Busbar 1 (STS1-STS5) due to considerations of the feeder line capacity. - Power limitation on Busbar 2 (STS6-STS10) due to considerations of the feeder line capacity. - The PR calculation for STS 1 & STS 2 is done manually because WS 5 is still under repair (since 1 June 2025)
A9: 45833 | B9: 236808 | C9: 4.14 | D9: 3.393558 | E9: 0.8197 | F9: 0.99 | G9: 73676 | H9: 11475 | I9: 27997.5 | J9: 59929.5 | K9: 54202 | L9: 227280 | M9: 277065.83 | N9: 49785.83 | O9: 277065.83 | P9: 17110 | Q9: 16870 | R9: 15370 | S9: 19210 | T9: 19610 | U9: 34920 | V9: 29440 | W9: 29820 | X9: 35330 | Y9: 30170 | Z9: 247850 | AA9: 297635.83 | AB9: 0.51 | AC9: 0.5 | AD9: 0.52 | AE9: 0.51 | AF9: 0.52 | AG9: 0.89 | AH9: 0.87 | AI9: 0.88 | AJ9: 0.9 | AK9: 0.89 | AL9: 1.0905051 | AM9: 3.8750466 | AN9: 4.91 | AO9: 4.98 | AQ9: 4.97 | AS9: 4.9533333 | AT9: 0.6969 | AU9: 0.78231088 | AV9: 1 | AW9: 71500 | AX9: 56992 | AY9: - The measurement at Weather Station 3 (STS-6) and 5 (STS-2) is not normal. -The PR calculation for STS 6 & STS 8 is done manually because WS 3 is still under repair (since 15 March 2025) -The PR calculation for STS 1 & STS 2 is done manually because WS 5 is still under repair (since 1 June 2025) -Power limitation on Busbar 1 (STS1-STS5) due to considerations of the feeder line capacity. Busbar 1 just operate 1 20 kV coupler (OG.1) sts1 and sts2 are set with maximum performance for their output power and do not affect the setpoint for busbar 1 which remains at 22 MW. -Power limitation on Busbar 2 due to considerations of the feeder line capacity. Busbar 2 just operate 2 20 kV coupler (OG.4 & OG.5)
A10: 45832 | B10: 236808 | C10: 4.14 | D10: 3.393558 | E10: 0.8197 | F10: 0.99 | G10: 86021 | H10: 0 | I10: 34732.5 | J10: 41672.5 | K10: 37502 | L10: 199928 | M10: 201664.17 | N10: 1736.17 | O10: 201664.17 | P10: 14650 | Q10: 14550 | R10: 13220 | S10: 16350 | T10: 16960 | U10: 19660 | V10: 16830 | W10: 16780 | X10: 19120 | Y10: 17480 | Z10: 165600 | AA10: 167336.17 | AB10: 0.85 | AC10: 0.84 | AD10: 0.86 | AE10: 0.84 | AF10: 0.86 | AG10: 0.96 | AH10: 0.95 | AI10: 0.94 | AJ10: 0.93 | AK10: 0.98 | AL10: 0.82829819 | AM10: 2.8204779 | AN10: 2.57 | AO10: 2.6 | AQ10: 2.56 | AS10: 2.5766667 | AT10: 0.9 | AU10: 1.0946227 | AV10: 1 | AW10: 71500 | AX10: 56992 | AY10: - The measurement at Weather Station 3 (STS-6) and 5 (STS-2) is not normal. -The PR calculation for STS 6 & STS 8 is done manually because WS 3 is still under repair (since 15 March 2025) -The PR calculation for STS 1 & STS 2 is done manually because WS 5 is still under repair (since 1 June 2025) -Power limitation on Busbar 1 (STS1-STS5) due to considerations of the feeder line capacity. Busbar 1 just operate 1 20 kV coupler (OG.1) sts1 and sts2 are set with maximum performance for their output power and do not affect the setpoint for busbar 1 which remains at 22 MW.
A11: 45831 | B11: 236808 | C11: 4.14 | D11: 3.393558 | E11: 0.8197 | F11: 0.99 | G11: 54538 | H11: 40217 | I11: 40217 | J11: 36841 | K11: 38491 | L11: 210304 | M11: 212586.17 | N11: 2282.17 | O11: 212586.17 | P11: 24880 | Q11: 23970 | R11: 20630 | S11: 24470 | T11: 26540 | U11: 30980 | V11: 25490 | W11: 26520 | X11: 30220 | Y11: 27080 | Z11: 260780 | AA11: 263062.17 | AB11: 0.84 | AC11: 0.81 | AD11: 0.78 | AE11: 0.73 | AF11: 0.8 | AG11: 0.94 | AH11: 0.89 | AI11: 0.93 | AJ11: 0.91 | AK11: 0.95 | AL11: 1.2400145 | AM11: 2.9732331 | AN11: 4.13 | AO11: 4.34 | AQ11: 4.39 | AS11: 4.2866667 | AT11: 0.8582 | AU11: 0.69360027 | AV11: 1 | AW11: 71500 | AX11: 56992 | AY11: - The measurement at Weather Station 3 (STS-6) and 5 (STS-2) is not normal. -The PR calculation for STS 6 & STS 8 is done manually because WS 3 is still under repair (since 15 March 2025) -The PR calculation for STS 1 & STS 2 is done manually because WS 5 is still under repair (since 1 June 2025) -Power limitation on Busbar 1 (STS1-STS5) due to considerations of the feeder line capacity. Busbar 1 just operate 1 20 kV coupler (OG.1) sts1 and sts2 are set with maximum performance for their output power and do not affect the setpoint for busbar 1 which remains at 22 MW.
A12: 45830 | B12: 236808 | C12: 4.14 | D12: 3.393558 | E12: 0.8197 | F12: 0.99 | G12: 69586 | H12: 69490 | I12: 50931 | J12: 54771.5 | K12: 49372 | L12: 294150.5 | M12: 281081.5 | N12: 0 | O12: 294150.5 | P12: 23960 | Q12: 23860 | R12: 20880 | S12: 25650 | T12: 26740 | U12: 28590 | V12: 24720 | W12: 24110 | X12: 27050 | Y12: 25010 | Z12: 250570 | AA12: 250570 | AB12: 0.9 | AC12: 0.9 | AD12: 0.89 | AE12: 0.86 | AF12: 0.88 | AG12: 0.93 | AH12: 0.93 | AI12: 0.91 | AJ12: 0.88 | AK12: 0.94 | AL12: 0.85184285 | AM12: 4.113993 | AN12: 3.84 | AO12: 3.97 | AQ12: 3.93 | AS12: 3.9133333 | AT12: 0.9014 | AU12: 1.0512759 | AV12: 1 | AW12: 71500 | AX12: 56992 | AY12: - The measurement at Weather Station 3 (STS-6) and 5 (STS-2) is not normal. -The PR calculation for STS 6 & STS 8 is done manually because WS 3 is still under repair (since 15 March 2025) -The PR calculation for STS 1 & STS 2 is done manually because WS 5 is still under repair (since 1 June 2025) -sts1 and sts2 are set with maximum performance for their output power and do not affect the setpoint for busbar 1 which remains at 22 MW.
A13: 45829 | B13: 236808 | C13: 4.14 | D13: 3.393558 | E13: 0.8197 | F13: 0.99 | G13: 62249.5 | H13: 62073 | I13: 45598.5 | J13: 50191 | K13: 45519 | L13: 265631 | M13: 256677.83 | N13: 0 | O13: 265631 | P13: 28500 | Q13: 28420 | R13: 24570 | S13: 30100 | T13: 31490 | U13: 34890 | V13: 29520 | W13: 29420 | X13: 33750 | Y13: 30960 | Z13: 301620 | AA13: 301620 | AB13: 0.88 | AC13: 0.87 | AD13: 0.85 | AE13: 0.82 | AF13: 0.87 | AG13: 0.93 | AH13: 0.91 | AI13: 0.9 | AJ13: 0.9 | AK13: 0.95 | AL13: 1.1354849 | AM13: 3.7151189 | AN13: 4.7 | AO13: 4.77 | AQ13: 4.82 | AS13: 4.7633333 | AT13: 0.8871 | AU13: 0.77994098 | AV13: 1 | AW13: 71500 | AX13: 56992 | AY13: - The measurement at Weather Station 3 (STS-6) and 5 (STS-2) is not normal. -The PR calculation for STS 6 & STS 8 is done manually because WS 3 is still under repair (since 15 March 2025) -The PR calculation for STS 1 & STS 2 is done manually because WS 5 is still under repair (since 1 June 2025) -sts1 and sts2 are set with maximum performance for their output power and do not affect the setpoint for busbar 1 which remains at 22 MW.
A14: 45828 | B14: 236808 | C14: 4.14 | D14: 3.393558 | E14: 0.8197 | F14: 0.99 | G14: 56417 | H14: 56360 | I14: 39968.5 | J14: 44774 | K14: 40778 | L14: 238297.5 | M14: 218482.5 | N14: 0 | O14: 238297.5 | P14: 17480 | Q14: 17350 | R14: 15360 | S14: 18790 | T14: 19980 | U14: 20650 | V14: 17460 | W14: 17460 | X14: 19770 | Y14: 18030 | Z14: 182330 | AA14: 182330 | AB14: 0.95 | AC14: 0.94 | AD14: 0.93 | AE14: 0.9 | AF14: 0.96 | AG14: 0.97 | AH14: 0.94 | AI14: 0.94 | AJ14: 0.93 | AK14: 0.97 | AL14: 0.76513602 | AM14: 3.3328322 | AN14: 2.67 | AO14: 2.74 | AQ14: 2.74 | AS14: 2.7166667 | AT14: 0.9428 | AU14: 1.2268094 | AV14: 1 | AW14: 71500 | AX14: 56992 | AY14: - The measurement at Weather Station 3 (STS-6) and 5 (STS-2) is not normal. -The PR calculation for STS 6 & STS 8 is done manually because WS 3 is still under repair (since 15 March 2025) -The PR calculation for STS 1 & STS 2 is done manually because WS 5 is still under repair (since 1 June 2025) -sts1 and sts2 are set with maximum performance for their output power and do not affect the setpoint for busbar 1 which remains at 22 MW.
A15: 45827 | B15: 236808 | C15: 4.14 | D15: 3.393558 | E15: 0.8197 | F15: 0.99 | G15: 32619.78 | H15: 32624.04 | I15: 20927.5 | J15: 27328.5 | K15: 25555.56 | L15: 139055.38 | M15: 121976.67 | N15: 0 | O15: 139055.38 | P15: 11570 | Q15: 11570 | R15: 10240 | S15: 12670 | T15: 13340 | U15: 13170 | V15: 11760 | W15: 11550 | X15: 12680 | Y15: 11970 | Z15: 120520 | AA15: 120520 | AB15: 0.9316 | AC15: 0.9316 | AD15: 0.9276 | AE15: 0.9036 | AF15: 0.9511 | AG15: 0.9405 | AH15: 0.9698 | AI15: 0.9521 | AJ15: 0.9055 | AK15: 0.9866 | AL15: 0.86670505 | AM15: 1.9448305 | AN15: 1.75 | AO15: 1.84 | AQ15: 1.84 | AS15: 1.81 | AT15: 0.94 | AU15: 1.074492 | AV15: 1 | AW15: 71500 | AX15: 56992 | AY15: - The measurement at Weather Station 3 (STS-6) and 5 (STS-2) is not normal. -The PR calculation for STS 6 & STS 8 is done manually because WS 3 is still under repair (since 15 March 2025) -The PR calculation for STS 1 & STS 2 is done manually because WS 5 is still under repair (since 1 June 2025) -sts1 and sts2 are set with maximum performance for their output power and do not affect the setpoint for busbar 1 which remains at 22 MW.
A16: 45826 | B16: 236808 | C16: 4.14 | D16: 3.393558 | E16: 0.8197 | F16: 0.99 | G16: 20925.76 | H16: 57968.51 | I16: 38990.47 | J16: 43894.5 | K16: 39858.09 | L16: 201637.33 | M16: 236668 | N16: 35030.67 | O16: 236668 | P16: 17510 | Q16: 18310 | R16: 16270 | S16: 20140 | T16: 20940 | U16: 30650 | V16: 27230 | W16: 25760 | X16: 28840 | Y16: 26400 | Z16: 232050 | AA16: 267080.67 | AB16: 0.6147 | AC16: 0.6429 | AD16: 0.6427 | AE16: 0.6263 | AF16: 0.6121 | AG16: 0.9035 | AH16: 0.9265 | AI16: 0.8767 | AJ16: 0.8501 | AK16: 0.8984 | AL16: 1.1508286 | AM16: 3.310042 | AN16: 4.24 | AO16: 4.49 | AQ16: 4.22 | AS16: 4.3166667 | AT16: 0.7594 | AU16: 0.76680509 | AV16: 1 | AW16: 71500 | AX16: 56992 | AY16: - The measurement at Weather Station 3 (STS-6) and 5 (STS-2) is not normal. -The PR calculation for STS 6 & STS 8 is done manually because WS 3 is still under repair (since 15 March 2025) -The PR calculation for STS 1 & STS 2 is done manually because WS 5 is still under repair (since 1 June 2025) -Power limitation on Busbar 1 (STS1-STS5) due to considerations of the feeder line capacity. Busbar 1 just operate 1 20 kV coupler (OG.2) sts1 and sts2 are set with maximum performance for their output power and do not affect the setpoint for busbar 1 which remains at 22 MW. - External Outage at OG.1, Trip Earth Fault at OG.1 and GSK.3 due to disturbances at GSK.3 20 kV network distribution
A17: 45825 | B17: 236808 | C17: 4.14 | D17: 3.393558 | E17: 0.8197 | F17: 0.99 | G17: 0 | H17: 72100.39 | I17: 40733.36 | J17: 47085.5 | K17: 41366.03 | L17: 201285.28 | M17: 231263 | N17: 29977.72 | O17: 231263 | P17: 14660 | Q17: 14620 | R17: 13260 | S17: 16660 | T17: 16880 | U17: 30310 | V17: 25970 | W17: 26560 | X17: 29970 | Y17: 27950 | Z17: 216840 | AA17: 246817.72 | AB17: 0.5005 | AC17: 0.4989 | AD17: 0.5091 | AE17: 0.5037 | AF17: 0.5034 | AG17: 0.8812 | AH17: 0.8714 | AI17: 0.8912 | AJ17: 0.8711 | AK17: 0.938 | AL17: 1.077277 | AM17: 3.2344476 | AN17: 4.3 | AO17: 4.4 | AQ17: 4.34 | AS17: 4.3466667 | AT17: 0.6968 | AU17: 0.74412137 | AV17: 1 | AW17: 71500 | AX17: 56992 | AY17: - The measurement at Weather Station 3 (STS-6) and 5 (STS-2) is not normal. -The PR calculation for STS 6 & STS 8 is done manually because WS 3 is still under repair (since 15 March 2025) -The PR calculation for STS 1 & STS 2 is done manually because WS 5 is still under repair (since 1 June 2025) -Power limitation on Busbar 1 (STS1-STS5) due to considerations of the feeder line capacity. Busbar 1 just operate 1 20 kV coupler (OG.2) sts1 and sts2 are set with maximum performance for their output power and do not affect the setpoint for busbar 1 which remains at 22 MW. - External Outage at OG.1, Trip Earth Fault at OG.1 and GSK.3 due to disturbances at GSK.3 20 kV network distribution
A18: 45824 | B18: 236808 | C18: 4.14 | D18: 3.393558 | E18: 0.8197 | F18: 0.99 | G18: 0 | H18: 72780.54 | I18: 40781.75 | J18: 46534 | K18: 41946.55 | L18: 202042.84 | M18: 231811 | N18: 29768.16 | O18: 231811 | P18: 16060 | Q18: 15830 | R18: 14190 | S18: 17510 | T18: 18010 | U18: 25850 | V18: 23620 | W18: 24440 | X18: 28110 | Y18: 25080 | Z18: 208700 | AA18: 238468.16 | AB18: 0.5875 | AC18: 0.5791 | AD18: 0.5838 | AE18: 0.5675 | AF18: 0.5939 | AG18: 0.8327 | AH18: 0.8783 | AI18: 0.9091 | AJ18: 0.9056 | AK18: 0.9329 | AL18: 1.0329492 | AM18: 3.2421119 | AN18: 3.88 | AO18: 3.98 | AQ18: 4.05 | AS18: 3.97 | AT18: 0.737 | AU18: 0.81665287 | AV18: 1 | AW18: 71500 | AX18: 56992 | AY18: - The measurement at Weather Station 3 (STS-6) and 5 (STS-2) is not normal. -The PR calculation for STS 6 & STS 8 is done manually because WS 3 is still under repair (since 15 March 2025) -The PR calculation for STS 1 & STS 2 is done manually because WS 5 is still under repair (since 1 June 2025) -Power limitation on Busbar 1 (STS1-STS5) due to considerations of the feeder line capacity. Busbar 1 just operate 1 20 kV coupler (OG.2) sts1 and sts2 are set with maximum performance for their output power and do not affect the setpoint for busbar 1 which remains at 22 MW. - External Outage at OG.1, Trip Earth Fault at OG.1 and GSK.3 due to disturbances at GSK.3 20 kV network distribution
A19: 45823 | B19: 236808 | C19: 4.14 | D19: 3.393558 | E19: 0.8197 | F19: 0.99 | G19: 14364.66 | H19: 84765.77 | I19: 56930.26 | J19: 60042 | K19: 53586.66 | L19: 269689.35 | M19: 332228.83 | N19: 62539.48 | O19: 332228.83 | P19: 18600 | Q19: 18420 | R19: 16570 | S19: 20380 | T19: 21170 | U19: 29860 | V19: 29010 | W19: 30720 | X19: 35060 | Y19: 32380 | Z19: 252170 | AA19: 314709.48 | AB19: 0.5413 | AC19: 0.536 | AD19: 0.5425 | AE19: 0.5256 | AF19: 0.5438 | AG19: 0.7263 | AH19: 0.8145 | AI19: 0.8625 | AJ19: 0.8526 | AK19: 0.9091 | AL19: 0.93503878 | AM19: 4.6465571 | AN19: 5.14 | AO19: 5.11 | AQ19: 5.09 | AS19: 5.1133333 | AT19: 0.6854 | AU19: 0.9087139 | AV19: 0.997 | AW19: 71500 | AX19: 56992 | AY19: - The measurement at Weather Station 3 (STS-6) and 5 (STS-2) is not normal. -The PR calculation for STS 6 & STS 8 is done manually because WS 3 is still under repair (since 15 March 2025) -The PR calculation for STS 1 & STS 2 is done manually because WS 5 is still under repair (since 1 June 2025) -Power limitation on Busbar 1 (STS1-STS5) due to considerations of the feeder line capacity. Busbar 1 just operate 1 20 kV coupler (OG.2) sts1 and sts2 are set with maximum performance for their output power and do not affect the setpoint for busbar 1 which remains at 22 MW. - External Outage at OG.1, Trip Earth Fault at OG.1 and GSK.3 due to disturbances at GSK.3 20 kV network distribution
A20: 45822 | B20: 236808 | C20: 4.14 | D20: 3.393558 | E20: 0.8197 | F20: 0.99 | G20: 33127.69 | H20: 33155.04 | I20: 23352.12 | J20: 24656.5 | K20: 26573.4 | L20: 140864.75 | M20: 123842 | N20: 0 | O20: 140864.75 | P20: 13840 | Q20: 13770 | R20: 11990 | S20: 14610 | T20: 15440 | U20: 17080 | V20: 13480 | W20: 14400 | X20: 15660 | Y20: 14690 | Z20: 144960 | AA20: 144960 | AB20: 0.9072 | AC20: 0.9027 | AD20: 0.8841 | AE20: 0.8483 | AF20: 0.8732 | AG20: 0.9531 | AH20: 0.8682 | AI20: 0.9273 | AJ20: 0.8739 | AK20: 0.9461 | AL20: 1.0290722 | AM20: 1.9701364 | AN20: 2.24 | AO20: 2.32 | AQ20: 2.26 | AS20: 2.2733333 | AT20: 0.8984 | AU20: 0.8666289 | AV20: 0.997 | AW20: 71500 | AX20: 56992 | AY20: - The measurement at Weather Station 3 (STS-6) and 5 (STS-2) is not normal. -The PR calculation for STS 6 & STS 8 is done manually because WS 3 is still under repair (since 15 March 2025) -The PR calculation for STS 1 & STS 2 is done manually because WS 5 is still under repair (since 1 June 2025) -Power limitation on Busbar 1 (STS1-STS5) due to considerations of the feeder line capacity. sts1 and sts2 are set with maximum performance for their output power and do not affect the setpoint for busbar 1 which remains at 22 MW.
... A33: 45809 | B33: 236808 | C33: 4.14 | D33: 3.393558 | E33: 0.8197 | F33: 0.99 | G33: 39013.38 | H33: 38964.09 | I33: 26556.08 | J33: 31273.58 | K33: 24358 | L33: 160165.13 | M33: 141126.67 | N33: 0 | O33: 160165.13 | P33: 12280 | Q33: 12980 | R33: 11600 | S33: 14180 | T33: 14950 | U33: 14570 | V33: 12030 | W33: 12780 | X33: 14250 | Y33: 13110 | Z33: 132730 | AA33: 132730 | AB33: 0.9008 | AC33: 0.9518 | AD33: 0.9568 | AE33: 0.921 | AF33: 0.981 | AG33: 0.9439 | AH33: 0.8996 | AI33: 0.9557 | AJ33: 0.9232 | AK33: 0.9804 | AL33: 0.82870722 | AM33: 2.2400717 | AN33: 1.93 | AO33: 2 | AQ33: 2.02 | AS33: 1.9833333 | AT33: 0.9414 | AU33: 1.1294479 | AV33: 0.995 | AW33: 71500 | AX33: 56992 | AY33: - The measurement at Weather Station 3 (STS-6) and 5 (STS-2) is not normal. -The PR calculation for STS 6 & STS 8 is done manually because WS 3 is still under repair (since 15 March 2025) -The PR calculation for STS 1 & STS 2 is done manually because WS 5 is still under repair (since 1 June 2025) -Power limitation on Busbar 1 (STS1-STS5) due to considerations of the feeder line capacity. sts1 and sts2 are set with maximum performance for their output power and do not affect the setpoint for busbar 1 which remains at 22 MW.

Sheet Detail2
A1: Details for Sum of Total STS Generation (kWh) - Months (Date): Jun, Years (Date): 2025
A3: Date | B3: Energy (kWh) | C3: GHI | D3: SY | E3: PR | F3: Availability | G3: OG1 | H3: OG2 | I3: OG3 | J3: OG4 | K3: OG5 | L3: Total Meter Generation (kWh) | M3: PAE Energy (kWh) | N3: Curtailed Energy (kWh) | O3: Corrected Meter Generation (kWh) | P3: STS1 | Q3: STS2 | R3: STS3 | S3: STS4 | T3: STS5 | U3: STS6 | V3: STS7 | W3: STS8 | X3: STS9 | Y3: STS10 | Z3: Total STS Generation (kWh) | AA3: Corrected STS Generation (kWh) | AB3: STS12 | AC3: STS22 | AD3: STS32 | AE3: STS42 | AF3: STS52 | AG3: STS62 | AH3: STS72 | AI3: STS82 | AJ3: STS92 | AK3: STS102 | AL3: MTR-STS Ratio (Mtr/Inv) | AM3: Daily Specific Yield | AN3: WS01 | AO3: WS02 | AP3: WS03 | AQ3: WS04 | AR3: WS05 | AS3: Average GHI | AT3: Plant Performance Ratio (PR) | AU3: Corrected Plant PR | AV3: System Availability (%) | AW3: PV Capacity (kWp) | AX3: AC Capacity | AY3: Special remarks (any event happened causing low Performance?)
A4: 45838 | B4: 236808 | C4: 4.14 | D4: 3.393558 | E4: 0.8197 | F4: 0.99 | G4: 42671 | H4: 42681 | I4: 0 | J4: 46974 | K4: 42738 | L4: 175064 | M4: 158399.33 | N4: 0 | O4: 175064 | P4: 13140 | Q4: 13110 | R4: 11550 | S4: 14230 | T4: 14880 | U4: 15380 | V4: 12910 | W4: 13040 | X4: 14760 | Y4: 13390 | Z4: 136390 | AA4: 136390 | AB4: 0.9782 | AC4: 0.9762 | AD4: 0.9674 | AE4: 0.9385 | AF4: 0.9815 | AG4: 1.0016 | AH4: 0.9702 | AI4: 0.9803 | AJ4: 0.961 | AK4: 1 | AL4: 0.77908651 | AM4: 2.4484476 | AN4: 1.92 | AO4: 1.99 | AP4: 2.03 | AQ4: 1.99 | AS4: 1.9825 | AT4: 0.9761 | AU4: 1.2350303 | AV4: 1 | AW4: 71500 | AX4: 56992 | AY4: - The measurement at Weather Station 5 (STS-2) is not normal. - Power limitation on Busbar 1 (STS1-STS5) due to considerations of the feeder line capacity.
A5: 45837 | B5: 236808 | C5: 4.14 | D5: 3.393558 | E5: 0.8197 | F5: 0.99 | G5: 55263 | H5: 55091 | I5: 0 | J5: 61985 | K5: 56054 | L5: 228393 | M5: 256854.83 | N5: 28461.83 | O5: 256854.83 | P5: 25580 | Q5: 25320 | R5: 21970 | S5: 26670 | T5: 27760 | U5: 30830 | V5: 25930 | W5: 25980 | X5: 29550 | Y5: 26260 | Z5: 265850 | AA5: 294311.83 | AB5: 0.7994 | AC5: 0.7913 | AD5: 0.7725 | AE5: 0.7383 | AF5: 0.775 | AG5: 0.8342 | AH5: 0.8098 | AI5: 0.8114 | AJ5: 0.7994 | AK5: 0.8201 | AL5: 1.1640024 | AM5: 3.5923752 | AN5: 4.62 | AO5: 4.7 | AP5: 4.98 | AQ5: 4.74 | AS5: 4.76 | AT5: 0.7951 | AU5: 0.75470068 | AV5: 1 | AW5: 71500 | AX5: 56992 | AY5: - The measurement at Weather Station 5 (STS-2) is not normal. - Power limitation on Busbar 1 (STS1-STS5) due to considerations of the feeder line capacity.
A6: 45836 | B6: 236808 | C6: 4.14 | D6: 3.393558 | E6: 0.8197 | F6: 0.99 | G6: 61685 | H6: 61577 | I6: 0 | J6: 70367 | K6: 63559 | L6: 257188 | M6: 264190.67 | N6: 7002.67 | O6: 264190.67 | P6: 23170 | Q6: 22560 | R6: 20130 | S6: 24230 | T6: 25970 | U6: 27970 | V6: 24220 | W6: 24080 | X6: 28040 | Y6: 24880 | Z6: 245250 | AA6: 252252.67 | AB6: 0.8669 | AC6: 0.8439 | AD6: 0.8472 | AE6: 0.8031 | AF6: 0.8352 | AG6: 0.8675 | AH6: 0.8673 | AI6: 0.8622 | AJ6: 0.8696 | AK6: 0.8908 | AL6: 0.95358259 | AM6: 3.6949744 | AN6: 4.03 | AO6: 4.08 | AP6: 4.23 | AQ6: 3.96 | AS6: 4.075 | AT6: 0.8554 | AU6: 0.90674219 | AV6: 1 | AW6: 71500 | AX6: 56992 | AY6: - The measurement at Weather Station 5 (STS-2) is not normal. - Power limitation on Busbar 1 (STS1-STS5) due to considerations of the feeder line capacity.
A7: 45835 | B7: 236808 | C7: 4.14 | D7: 3.393558 | E7: 0.8197 | F7: 0.99 | G7: 72264 | H7: 72018 | I7: 0 | J7: 81406 | K7: 74203 | L7: 299891 | M7: 309808.5 | N7: 9917.5 | O7: 309808.5 | P7: 30360 | Q7: 29860 | R7: 26020 | S7: 31740 | T7: 32320 | U7: 35630 | V7: 30200 | W7: 29930 | X7: 33560 | Y7: 30300 | Z7: 309920 | AA7: 319837.5 | AB7: 0.8282 | AC7: 0.8147 | AD7: 0.7988 | AE7: 0.767 | AF7: 0.8002 | AG7: 0.8681 | AH7: 0.8495 | AI7: 0.8419 | AJ7: 0.8177 | AK7: 0.8523 | AL7: 1.0334422 | AM7: 4.332986 | AN7: 5.13 | AO7: 5.3 | AP7: 5.59 | AQ7: 5.43 | AS7: 5.3625 | AT7: 0.8238 | AU7: 0.80801604 | AV7: 1 | AW7: 71500 | AX7: 56992 | AY7: - The measurement at Weather Station 5 (STS-2) is not normal. - Power limitation on Busbar 1 (STS1-STS5) due to considerations of the feeder line capacity.
A8: 45834 | B8: 236808 | C8: 4.14 | D8: 3.393558 | E8: 0.8197 | F8: 0.99 | G8: 75976 | H8: 75877 | I8: 0 | J8: 83405 | K8: 76258 | L8: 311516 | M8: 300419.17 | N8: 0 | O8: 311516 | P8: 28600 | Q8: 28630 | R8: 25350 | S8: 31190 | T8: 32410 | U8: 34260 | V8: 29430 | W8: 28780 | X8: 31540 | Y8: 29660 | Z8: 299850 | AA8: 299850 | AB8: 0.89 | AC8: 0.89 | AD8: 0.89 | AE8: 0.86 | AF8: 0.88 | AG8: 0.93 | AH8: 0.92 | AI8: 0.9 | AJ8: 0.85 | AK8: 0.92 | AL8: 0.96255088 | AM8: 4.3568671 | AN8: 4.61 | AO8: 4.83 | AP8: 4.93 | AQ8: 4.73 | AS8: 4.775 | AT8: 0.89 | AU8: 0.91243291 | AV8: 1 | AW8: 71500 | AX8: 56992 | AY8: -The measurement at Weather Station 3 (STS-6) and 5 (STS-2) is not normal. - Power limitation on Busbar 1 (STS1-STS5) due to considerations of the feeder line capacity. - Power limitation on Busbar 2 (STS6-STS10) due to considerations of the feeder line capacity. - The PR calculation for STS 1 & STS 2 is done manually because WS 5 is still under repair (since 1 June 2025)
A9: 45833 | B9: 236808 | C9: 4.14 | D9: 3.393558 | E9: 0.8197 | F9: 0.99 | G9: 73676 | H9: 11475 | I9: 27997.5 | J9: 59929.5 | K9: 54202 | L9: 227280 | M9: 277065.83 | N9: 49785.83 | O9: 277065.83 | P9: 17110 | Q9: 16870 | R9: 15370 | S9: 19210 | T9: 19610 | U9: 34920 | V9: 29440 | W9: 29820 | X9: 35330 | Y9: 30170 | Z9: 247850 | AA9: 297635.83 | AB9: 0.51 | AC9: 0.5 | AD9: 0.52 | AE9: 0.51 | AF9: 0.52 | AG9: 0.89 | AH9: 0.87 | AI9: 0.88 | AJ9: 0.9 | AK9: 0.89 | AL9: 1.0905051 | AM9: 3.8750466 | AN9: 4.91 | AO9: 4.98 | AQ9: 4.97 | AS9: 4.9533333 | AT9: 0.6969 | AU9: 0.78231088 | AV9: 1 | AW9: 71500 | AX9: 56992 | AY9: - The measurement at Weather Station 3 (STS-6) and 5 (STS-2) is not normal. -The PR calculation for STS 6 & STS 8 is done manually because WS 3 is still under repair (since 15 March 2025) -The PR calculation for STS 1 & STS 2 is done manually because WS 5 is still under repair (since 1 June 2025) -Power limitation on Busbar 1 (STS1-STS5) due to considerations of the feeder line capacity. Busbar 1 just operate 1 20 kV coupler (OG.1) sts1 and sts2 are set with maximum performance for their output power and do not affect the setpoint for busbar 1 which remains at 22 MW. -Power limitation on Busbar 2 due to considerations of the feeder line capacity. Busbar 2 just operate 2 20 kV coupler (OG.4 & OG.5)
A10: 45832 | B10: 236808 | C10: 4.14 | D10: 3.393558 | E10: 0.8197 | F10: 0.99 | G10: 86021 | H10: 0 | I10: 34732.5 | J10: 41672.5 | K10: 37502 | L10: 199928 | M10: 201664.17 | N10: 1736.17 | O10: 201664.17 | P10: 14650 | Q10: 14550 | R10: 13220 | S10: 16350 | T10: 16960 | U10: 19660 | V10: 16830 | W10: 16780 | X10: 19120 | Y10: 17480 | Z10: 165600 | AA10: 167336.17 | AB10: 0.85 | AC10: 0.84 | AD10: 0.86 | AE10: 0.84 | AF10: 0.86 | AG10: 0.96 | AH10: 0.95 | AI10: 0.94 | AJ10: 0.93 | AK10: 0.98 | AL10: 0.82829819 | AM10: 2.8204779 | AN10: 2.57 | AO10: 2.6 | AQ10: 2.56 | AS10: 2.5766667 | AT10: 0.9 | AU10: 1.0946227 | AV10: 1 | AW10: 71500 | AX10: 56992 | AY10: - The measurement at Weather Station 3 (STS-6) and 5 (STS-2) is not normal. -The PR calculation for STS 6 & STS 8 is done manually because WS 3 is still under repair (since 15 March 2025) -The PR calculation for STS 1 & STS 2 is done manually because WS 5 is still under repair (since 1 June 2025) -Power limitation on Busbar 1 (STS1-STS5) due to considerations of the feeder line capacity. Busbar 1 just operate 1 20 kV coupler (OG.1) sts1 and sts2 are set with maximum performance for their output power and do not affect the setpoint for busbar 1 which remains at 22 MW.
A11: 45831 | B11: 236808 | C11: 4.14 | D11: 3.393558 | E11: 0.8197 | F11: 0.99 | G11: 54538 | H11: 40217 | I11: 40217 | J11: 36841 | K11: 38491 | L11: 210304 | M11: 212586.17 | N11: 2282.17 | O11: 212586.17 | P11: 24880 | Q11: 23970 | R11: 20630 | S11: 24470 | T11: 26540 | U11: 30980 | V11: 25490 | W11: 26520 | X11: 30220 | Y11: 27080 | Z11: 260780 | AA11: 263062.17 | AB11: 0.84 | AC11: 0.81 | AD11: 0.78 | AE11: 0.73 | AF11: 0.8 | AG11: 0.94 | AH11: 0.89 | AI11: 0.93 | AJ11: 0.91 | AK11: 0.95 | AL11: 1.2400145 | AM11: 2.9732331 | AN11: 4.13 | AO11: 4.34 | AQ11: 4.39 | AS11: 4.2866667 | AT11: 0.8582 | AU11: 0.69360027 | AV11: 1 | AW11: 71500 | AX11: 56992 | AY11: - The measurement at Weather Station 3 (STS-6) and 5 (STS-2) is not normal. -The PR calculation for STS 6 & STS 8 is done manually because WS 3 is still under repair (since 15 March 2025) -The PR calculation for STS 1 & STS 2 is done manually because WS 5 is still under repair (since 1 June 2025) -Power limitation on Busbar 1 (STS1-STS5) due to considerations of the feeder line capacity. Busbar 1 just operate 1 20 kV coupler (OG.1) sts1 and sts2 are set with maximum performance for their output power and do not affect the setpoint for busbar 1 which remains at 22 MW.
A12: 45830 | B12: 236808 | C12: 4.14 | D12: 3.393558 | E12: 0.8197 | F12: 0.99 | G12: 69586 | H12: 69490 | I12: 50931 | J12: 54771.5 | K12: 49372 | L12: 294150.5 | M12: 281081.5 | N12: 0 | O12: 294150.5 | P12: 23960 | Q12: 23860 | R12: 20880 | S12: 25650 | T12: 26740 | U12: 28590 | V12: 24720 | W12: 24110 | X12: 27050 | Y12: 25010 | Z12: 250570 | AA12: 250570 | AB12: 0.9 | AC12: 0.9 | AD12: 0.89 | AE12: 0.86 | AF12: 0.88 | AG12: 0.93 | AH12: 0.93 | AI12: 0.91 | AJ12: 0.88 | AK12: 0.94 | AL12: 0.85184285 | AM12: 4.113993 | AN12: 3.84 | AO12: 3.97 | AQ12: 3.93 | AS12: 3.9133333 | AT12: 0.9014 | AU12: 1.0512759 | AV12: 1 | AW12: 71500 | AX12: 56992 | AY12: - The measurement at Weather Station 3 (STS-6) and 5 (STS-2) is not normal. -The PR calculation for STS 6 & STS 8 is done manually because WS 3 is still under repair (since 15 March 2025) -The PR calculation for STS 1 & STS 2 is done manually because WS 5 is still under repair (since 1 June 2025) -sts1 and sts2 are set with maximum performance for their output power and do not affect the setpoint for busbar 1 which remains at 22 MW.
A13: 45829 | B13: 236808 | C13: 4.14 | D13: 3.393558 | E13: 0.8197 | F13: 0.99 | G13: 62249.5 | H13: 62073 | I13: 45598.5 | J13: 50191 | K13: 45519 | L13: 265631 | M13: 256677.83 | N13: 0 | O13: 265631 | P13: 28500 | Q13: 28420 | R13: 24570 | S13: 30100 | T13: 31490 | U13: 34890 | V13: 29520 | W13: 29420 | X13: 33750 | Y13: 30960 | Z13: 301620 | AA13: 301620 | AB13: 0.88 | AC13: 0.87 | AD13: 0.85 | AE13: 0.82 | AF13: 0.87 | AG13: 0.93 | AH13: 0.91 | AI13: 0.9 | AJ13: 0.9 | AK13: 0.95 | AL13: 1.1354849 | AM13: 3.7151189 | AN13: 4.7 | AO13: 4.77 | AQ13: 4.82 | AS13: 4.7633333 | AT13: 0.8871 | AU13: 0.77994098 | AV13: 1 | AW13: 71500 | AX13: 56992 | AY13: - The measurement at Weather Station 3 (STS-6) and 5 (STS-2) is not normal. -The PR calculation for STS 6 & STS 8 is done manually because WS 3 is still under repair (since 15 March 2025) -The PR calculation for STS 1 & STS 2 is done manually because WS 5 is still under repair (since 1 June 2025) -sts1 and sts2 are set with maximum performance for their output power and do not affect the setpoint for busbar 1 which remains at 22 MW.
A14: 45828 | B14: 236808 | C14: 4.14 | D14: 3.393558 | E14: 0.8197 | F14: 0.99 | G14: 56417 | H14: 56360 | I14: 39968.5 | J14: 44774 | K14: 40778 | L14: 238297.5 | M14: 218482.5 | N14: 0 | O14: 238297.5 | P14: 17480 | Q14: 17350 | R14: 15360 | S14: 18790 | T14: 19980 | U14: 20650 | V14: 17460 | W14: 17460 | X14: 19770 | Y14: 18030 | Z14: 182330 | AA14: 182330 | AB14: 0.95 | AC14: 0.94 | AD14: 0.93 | AE14: 0.9 | AF14: 0.96 | AG14: 0.97 | AH14: 0.94 | AI14: 0.94 | AJ14: 0.93 | AK14: 0.97 | AL14: 0.76513602 | AM14: 3.3328322 | AN14: 2.67 | AO14: 2.74 | AQ14: 2.74 | AS14: 2.7166667 | AT14: 0.9428 | AU14: 1.2268094 | AV14: 1 | AW14: 71500 | AX14: 56992 | AY14: - The measurement at Weather Station 3 (STS-6) and 5 (STS-2) is not normal. -The PR calculation for STS 6 & STS 8 is done manually because WS 3 is still under repair (since 15 March 2025) -The PR calculation for STS 1 & STS 2 is done manually because WS 5 is still under repair (since 1 June 2025) -sts1 and sts2 are set with maximum performance for their output power and do not affect the setpoint for busbar 1 which remains at 22 MW.
A15: 45827 | B15: 236808 | C15: 4.14 | D15: 3.393558 | E15: 0.8197 | F15: 0.99 | G15: 32619.78 | H15: 32624.04 | I15: 20927.5 | J15: 27328.5 | K15: 25555.56 | L15: 139055.38 | M15: 121976.67 | N15: 0 | O15: 139055.38 | P15: 11570 | Q15: 11570 | R15: 10240 | S15: 12670 | T15: 13340 | U15: 13170 | V15: 11760 | W15: 11550 | X15: 12680 | Y15: 11970 | Z15: 120520 | AA15: 120520 | AB15: 0.9316 | AC15: 0.9316 | AD15: 0.9276 | AE15: 0.9036 | AF15: 0.9511 | AG15: 0.9405 | AH15: 0.9698 | AI15: 0.9521 | AJ15: 0.9055 | AK15: 0.9866 | AL15: 0.86670505 | AM15: 1.9448305 | AN15: 1.75 | AO15: 1.84 | AQ15: 1.84 | AS15: 1.81 | AT15: 0.94 | AU15: 1.074492 | AV15: 1 | AW15: 71500 | AX15: 56992 | AY15: - The measurement at Weather Station 3 (STS-6) and 5 (STS-2) is not normal. -The PR calculation for STS 6 & STS 8 is done manually because WS 3 is still under repair (since 15 March 2025) -The PR calculation for STS 1 & STS 2 is done manually because WS 5 is still under repair (since 1 June 2025) -sts1 and sts2 are set with maximum performance for their output power and do not affect the setpoint for busbar 1 which remains at 22 MW.
A16: 45826 | B16: 236808 | C16: 4.14 | D16: 3.393558 | E16: 0.8197 | F16: 0.99 | G16: 20925.76 | H16: 57968.51 | I16: 38990.47 | J16: 43894.5 | K16: 39858.09 | L16: 201637.33 | M16: 236668 | N16: 35030.67 | O16: 236668 | P16: 17510 | Q16: 18310 | R16: 16270 | S16: 20140 | T16: 20940 | U16: 30650 | V16: 27230 | W16: 25760 | X16: 28840 | Y16: 26400 | Z16: 232050 | AA16: 267080.67 | AB16: 0.6147 | AC16: 0.6429 | AD16: 0.6427 | AE16: 0.6263 | AF16: 0.6121 | AG16: 0.9035 | AH16: 0.9265 | AI16: 0.8767 | AJ16: 0.8501 | AK16: 0.8984 | AL16: 1.1508286 | AM16: 3.310042 | AN16: 4.24 | AO16: 4.49 | AQ16: 4.22 | AS16: 4.3166667 | AT16: 0.7594 | AU16: 0.76680509 | AV16: 1 | AW16: 71500 | AX16: 56992 | AY16: - The measurement at Weather Station 3 (STS-6) and 5 (STS-2) is not normal. -The PR calculation for STS 6 & STS 8 is done manually because WS 3 is still under repair (since 15 March 2025) -The PR calculation for STS 1 & STS 2 is done manually because WS 5 is still under repair (since 1 June 2025) -Power limitation on Busbar 1 (STS1-STS5) due to considerations of the feeder line capacity. Busbar 1 just operate 1 20 kV coupler (OG.2) sts1 and sts2 are set with maximum performance for their output power and do not affect the setpoint for busbar 1 which remains at 22 MW. - External Outage at OG.1, Trip Earth Fault at OG.1 and GSK.3 due to disturbances at GSK.3 20 kV network distribution
A17: 45825 | B17: 236808 | C17: 4.14 | D17: 3.393558 | E17: 0.8197 | F17: 0.99 | G17: 0 | H17: 72100.39 | I17: 40733.36 | J17: 47085.5 | K17: 41366.03 | L17: 201285.28 | M17: 231263 | N17: 29977.72 | O17: 231263 | P17: 14660 | Q17: 14620 | R17: 13260 | S17: 16660 | T17: 16880 | U17: 30310 | V17: 25970 | W17: 26560 | X17: 29970 | Y17: 27950 | Z17: 216840 | AA17: 246817.72 | AB17: 0.5005 | AC17: 0.4989 | AD17: 0.5091 | AE17: 0.5037 | AF17: 0.5034 | AG17: 0.8812 | AH17: 0.8714 | AI17: 0.8912 | AJ17: 0.8711 | AK17: 0.938 | AL17: 1.077277 | AM17: 3.2344476 | AN17: 4.3 | AO17: 4.4 | AQ17: 4.34 | AS17: 4.3466667 | AT17: 0.6968 | AU17: 0.74412137 | AV17: 1 | AW17: 71500 | AX17: 56992 | AY17: - The measurement at Weather Station 3 (STS-6) and 5 (STS-2) is not normal. -The PR calculation for STS 6 & STS 8 is done manually because WS 3 is still under repair (since 15 March 2025) -The PR calculation for STS 1 & STS 2 is done manually because WS 5 is still under repair (since 1 June 2025) -Power limitation on Busbar 1 (STS1-STS5) due to considerations of the feeder line capacity. Busbar 1 just operate 1 20 kV coupler (OG.2) sts1 and sts2 are set with maximum performance for their output power and do not affect the setpoint for busbar 1 which remains at 22 MW. - External Outage at OG.1, Trip Earth Fault at OG.1 and GSK.3 due to disturbances at GSK.3 20 kV network distribution
A18: 45824 | B18: 236808 | C18: 4.14 | D18: 3.393558 | E18: 0.8197 | F18: 0.99 | G18: 0 | H18: 72780.54 | I18: 40781.75 | J18: 46534 | K18: 41946.55 | L18: 202042.84 | M18: 231811 | N18: 29768.16 | O18: 231811 | P18: 16060 | Q18: 15830 | R18: 14190 | S18: 17510 | T18: 18010 | U18: 25850 | V18: 23620 | W18: 24440 | X18: 28110 | Y18: 25080 | Z18: 208700 | AA18: 238468.16 | AB18: 0.5875 | AC18: 0.5791 | AD18: 0.5838 | AE18: 0.5675 | AF18: 0.5939 | AG18: 0.8327 | AH18: 0.8783 | AI18: 0.9091 | AJ18: 0.9056 | AK18: 0.9329 | AL18: 1.0329492 | AM18: 3.2421119 | AN18: 3.88 | AO18: 3.98 | AQ18: 4.05 | AS18: 3.97 | AT18: 0.737 | AU18: 0.81665287 | AV18: 1 | AW18: 71500 | AX18: 56992 | AY18: - The measurement at Weather Station 3 (STS-6) and 5 (STS-2) is not normal. -The PR calculation for STS 6 & STS 8 is done manually because WS 3 is still under repair (since 15 March 2025) -The PR calculation for STS 1 & STS 2 is done manually because WS 5 is still under repair (since 1 June 2025) -Power limitation on Busbar 1 (STS1-STS5) due to considerations of the feeder line capacity. Busbar 1 just operate 1 20 kV coupler (OG.2) sts1 and sts2 are set with maximum performance for their output power and do not affect the setpoint for busbar 1 which remains at 22 MW. - External Outage at OG.1, Trip Earth Fault at OG.1 and GSK.3 due to disturbances at GSK.3 20 kV network distribution
A19: 45823 | B19: 236808 | C19: 4.14 | D19: 3.393558 | E19: 0.8197 | F19: 0.99 | G19: 14364.66 | H19: 84765.77 | I19: 56930.26 | J19: 60042 | K19: 53586.66 | L19: 269689.35 | M19: 332228.83 | N19: 62539.48 | O19: 332228.83 | P19: 18600 | Q19: 18420 | R19: 16570 | S19: 20380 | T19: 21170 | U19: 29860 | V19: 29010 | W19: 30720 | X19: 35060 | Y19: 32380 | Z19: 252170 | AA19: 314709.48 | AB19: 0.5413 | AC19: 0.536 | AD19: 0.5425 | AE19: 0.5256 | AF19: 0.5438 | AG19: 0.7263 | AH19: 0.8145 | AI19: 0.8625 | AJ19: 0.8526 | AK19: 0.9091 | AL19: 0.93503878 | AM19: 4.6465571 | AN19: 5.14 | AO19: 5.11 | AQ19: 5.09 | AS19: 5.1133333 | AT19: 0.6854 | AU19: 0.9087139 | AV19: 0.997 | AW19: 71500 | AX19: 56992 | AY19: - The measurement at Weather Station 3 (STS-6) and 5 (STS-2) is not normal. -The PR calculation for STS 6 & STS 8 is done manually because WS 3 is still under repair (since 15 March 2025) -The PR calculation for STS 1 & STS 2 is done manually because WS 5 is still under repair (since 1 June 2025) -Power limitation on Busbar 1 (STS1-STS5) due to considerations of the feeder line capacity. Busbar 1 just operate 1 20 kV coupler (OG.2) sts1 and sts2 are set with maximum performance for their output power and do not affect the setpoint for busbar 1 which remains at 22 MW. - External Outage at OG.1, Trip Earth Fault at OG.1 and GSK.3 due to disturbances at GSK.3 20 kV network distribution
A20: 45822 | B20: 236808 | C20: 4.14 | D20: 3.393558 | E20: 0.8197 | F20: 0.99 | G20: 33127.69 | H20: 33155.04 | I20: 23352.12 | J20: 24656.5 | K20: 26573.4 | L20: 140864.75 | M20: 123842 | N20: 0 | O20: 140864.75 | P20: 13840 | Q20: 13770 | R20: 11990 | S20: 14610 | T20: 15440 | U20: 17080 | V20: 13480 | W20: 14400 | X20: 15660 | Y20: 14690 | Z20: 144960 | AA20: 144960 | AB20: 0.9072 | AC20: 0.9027 | AD20: 0.8841 | AE20: 0.8483 | AF20: 0.8732 | AG20: 0.9531 | AH20: 0.8682 | AI20: 0.9273 | AJ20: 0.8739 | AK20: 0.9461 | AL20: 1.0290722 | AM20: 1.9701364 | AN20: 2.24 | AO20: 2.32 | AQ20: 2.26 | AS20: 2.2733333 | AT20: 0.8984 | AU20: 0.8666289 | AV20: 0.997 | AW20: 71500 | AX20: 56992 | AY20: - The measurement at Weather Station 3 (STS-6) and 5 (STS-2) is not normal. -The PR calculation for STS 6 & STS 8 is done manually because WS 3 is still under repair (since 15 March 2025) -The PR calculation for STS 1 & STS 2 is done manually because WS 5 is still under repair (since 1 June 2025) -Power limitation on Busbar 1 (STS1-STS5) due to considerations of the feeder line capacity. sts1 and sts2 are set with maximum performance for their output power and do not affect the setpoint for busbar 1 which remains at 22 MW.
... A33: 45809 | B33: 236808 | C33: 4.14 | D33: 3.393558 | E33: 0.8197 | F33: 0.99 | G33: 39013.38 | H33: 38964.09 | I33: 26556.08 | J33: 31273.58 | K33: 24358 | L33: 160165.13 | M33: 141126.67 | N33: 0 | O33: 160165.13 | P33: 12280 | Q33: 12980 | R33: 11600 | S33: 14180 | T33: 14950 | U33: 14570 | V33: 12030 | W33: 12780 | X33: 14250 | Y33: 13110 | Z33: 132730 | AA33: 132730 | AB33: 0.9008 | AC33: 0.9518 | AD33: 0.9568 | AE33: 0.921 | AF33: 0.981 | AG33: 0.9439 | AH33: 0.8996 | AI33: 0.9557 | AJ33: 0.9232 | AK33: 0.9804 | AL33: 0.82870722 | AM33: 2.2400717 | AN33: 1.93 | AO33: 2 | AQ33: 2.02 | AS33: 1.9833333 | AT33: 0.9414 | AU33: 1.1294479 | AV33: 0.995 | AW33: 71500 | AX33: 56992 | AY33: - The measurement at Weather Station 3 (STS-6) and 5 (STS-2) is not normal. -The PR calculation for STS 6 & STS 8 is done manually because WS 3 is still under repair (since 15 March 2025) -The PR calculation for STS 1 & STS 2 is done manually because WS 5 is still under repair (since 1 June 2025) -Power limitation on Busbar 1 (STS1-STS5) due to considerations of the feeder line capacity. sts1 and sts2 are set with maximum performance for their output power and do not affect the setpoint for busbar 1 which remains at 22 MW.

Sheet Summary (PV)
B1: STS Generation (kWh) | O1: Propotional Setpoint (kW)
A2: Date | B2: WB01 | C2: WB02 | D2: WB03 | E2: WB04 | F2: WB05 | G2: WB06 | H2: WB07 | I2: WB08 | J2: WB09 | K2: WB10 | L2: Total STS Generation (kWh) | M2: PAE Energy (kWh) from 00.00 to 24.00 | N2: Generation STS (kWh) | O2: Busbar 1 (WB 01 - WB 5) | P2: Busbar 2 (WB 06 - WB 10) | Q2: Deem Dispatch (kWh) | R2: Curtailment
A3: 45627 | B3: 8930 | C3: 8830 | L3: =SUM(B3:K3) -> 17760 | N3: =IF(OR(O3<24300,P3<25700),MAX(L3,M3),L3) -> 17760
A4: 45628 | B4: 15880 | C4: 13060 | D4: 20130 | L4: =SUM(B4:K4) -> 49070 | N4: =IF(OR(O4<24300,P4<25700),MAX(L4,M4),L4) -> 49070
A5: 45629 | B5: 5100 | C5: 4020 | D5: 0 | E5: 13370 | L5: =SUM(B5:K5) -> 22490 | N5: =IF(OR(O5<24300,P5<25700),MAX(L5,M5),L5) -> 22490
A6: 45630 | B6: 5460 | C6: 5410 | D6: 0 | E6: 9140 | L6: =SUM(B6:K6) -> 20010 | N6: =IF(OR(O6<24300,P6<25700),MAX(L6,M6),L6) -> 20010
A7: 45631 | B7: 0 | C7: 0 | D7: 0 | E7: 23100 | L7: =SUM(B7:K7) -> 23100 | N7: =IF(OR(O7<24300,P7<25700),MAX(L7,M7),L7) -> 23100
A8: 45632 | B8: 0 | C8: 0 | D8: 0 | E8: 23100 | L8: =SUM(B8:K8) -> 23100 | N8: =IF(OR(O8<24300,P8<25700),MAX(L8,M8),L8) -> 23100
A9: 45633 | B9: 0 | C9: 0 | D9: 14260 | E9: 21000 | F9: 14880 | L9: =SUM(B9:K9) -> 50140 | N9: =IF(OR(O9<24300,P9<25700),MAX(L9,M9),L9) -> 50140
A10: 45634 | B10: 0 | C10: 0 | D10: 6460 | E10: 7910 | F10: 33250 | L10: =SUM(B10:K10) -> 47620 | N10: =IF(OR(O10<24300,P10<25700),MAX(L10,M10),L10) -> 47620
A11: 45635 | B11: 0 | C11: 0 | D11: 25710 | E11: 11120 | F11: 11480 | L11: =SUM(B11:K11) -> 48310 | N11: =IF(OR(O11<24300,P11<25700),MAX(L11,M11),L11) -> 48310
A12: 45636 | B12: 0 | C12: 0 | D12: 25710 | E12: 11120 | F12: 11480 | L12: =SUM(B12:K12) -> 48310 | N12: =IF(OR(O12<24300,P12<25700),MAX(L12,M12),L12) -> 48310
A13: 45637 | B13: 0 | C13: 0 | D13: 21420 | E13: 10410 | F13: 11140 | L13: =SUM(B13:K13) -> 42970 | N13: =IF(OR(O13<24300,P13<25700),MAX(L13,M13),L13) -> 42970
A14: 45638 | B14: 10800 | C14: 10930 | D14: 15220 | E14: 7400 | F14: 7430 | L14: =SUM(B14:K14) -> 51780 | N14: =IF(OR(O14<24300,P14<25700),MAX(L14,M14),L14) -> 51780
A15: 45639 | B15: 10870 | C15: 10990 | D15: 3410 | E15: 3440 | F15: 3450 | L15: =SUM(B15:K15) -> 32160 | N15: =IF(OR(O15<24300,P15<25700),MAX(L15,M15),L15) -> 32160
A16: 45640 | B16: 26020 | C16: 26360 | D16: 16600 | E16: 17560 | F16: 17560 | L16: =SUM(B16:K16) -> 104100 | N16: =IF(OR(O16<24300,P16<25700),MAX(L16,M16),L16) -> 104100
A17: 45641 | B17: 19230 | C17: 19460 | D17: 15430 | E17: 17140 | F17: 17420 | L17: =SUM(B17:K17) -> 88680 | N17: =IF(OR(O17<24300,P17<25700),MAX(L17,M17),L17) -> 88680
A18: 45642 | B18: 9650 | C18: 9840 | D18: 8720 | E18: 11040 | F18: 11350 | L18: =SUM(B18:K18) -> 50600 | N18: =IF(OR(O18<24300,P18<25700),MAX(L18,M18),L18) -> 50600
A19: 45643 | B19: 19800 | C19: 19990 | D19: 13340 | E19: 17270 | F19: 17600 | L19: =SUM(B19:K19) -> 88000 | N19: =IF(OR(O19<24300,P19<25700),MAX(L19,M19),L19) -> 88000
A20: 45644 | B20: 33730 | C20: 33990 | D20: 17410 | E20: 23730 | F20: 23930 | L20: =SUM(B20:K20) -> 132790 | N20: =IF(OR(O20<24300,P20<25700),MAX(L20,M20),L20) -> 132790
... A23: 45647 | B23: 24870 | C23: 25130 | D23: 0 | E23: 28240 | F23: 0 | L23: =SUM(B23:K23) -> 78240 | N23: =IF(OR(O23<24300,P23<25700),MAX(L23,M23),L23) -> 78240
A24: 45648 | B24: 20880 | C24: 21110 | D24: 0 | E24: 23900 | F24: 0 | G24: 3620 | H24: 10060 | I24: 73400 | J24: 0.31 | K24: 73380 | L24: =SUM(B24:K24) -> 226350.31 | N24: =IF(OR(O24<24300,P24<25700),MAX(L24,M24),L24) -> 226350.31
A25: 45649 | B25: 24210 | C25: 24470 | D25: 0 | E25: 27770 | F25: 0 | G25: 4270 | H25: 25090 | I25: 9440 | J25: 12690 | K25: 25970 | L25: =SUM(B25:K25) -> 153910 | N25: =IF(OR(O25<24300,P25<25700),MAX(L25,M25),L25) -> 153910
A26: 45650 | B26: 19820 | C26: 11440 | D26: 16980 | E26: 30740 | F26: 22070 | G26: 4920 | H26: 27360 | I26: 0.53 | J26: 14020 | K26: 22470 | L26: =SUM(B26:K26) -> 169820.53 | N26: =IF(OR(O26<24300,P26<25700),MAX(L26,M26),L26) -> 169820.53
A27: 45651 | B27: 15250 | C27: 1200 | D27: 13830 | E27: 17390 | F27: 18120 | G27: 4050 | H27: 15800 | I27: 9970 | J27: 8890 | K27: 16270 | L27: =SUM(B27:K27) -> 120770 | N27: =IF(OR(O27<24300,P27<25700),MAX(L27,M27),L27) -> 120770
A28: 45652 | B28: 20450 | C28: 18450 | D28: 18860 | E28: 21670 | F28: 24950 | G28: 2150 | H28: 21910 | I28: 18700 | J28: 12810 | K28: 22980 | L28: =SUM(B28:K28) -> 182930 | N28: =IF(OR(O28<24300,P28<25700),MAX(L28,M28),L28) -> 182930
A29: 45653 | B29: 22970 | C29: 19990 | D29: 21520 | E29: 22380 | F29: 28250 | G29: 9830 | H29: 24540 | I29: 24310 | J29: 14210 | K29: 25440 | L29: =SUM(B29:K29) -> 213440 | N29: =IF(OR(O29<24300,P29<25700),MAX(L29,M29),L29) -> 213440
A30: 45654 | B30: 25840 | C30: 20490 | D30: 25890 | E30: 23040 | F30: 33810 | G30: 9720 | H30: 28890 | I30: 28170 | J30: 17300 | K30: 28540 | L30: =SUM(B30:K30) -> 241690 | M30: 296695.84 | N30: =IF(OR(O30<24300,P30<25700),MAX(L30,M30),L30) -> 296695.84 | O30: 21155 | P30: 21130 | Q30: 0 | R30: =IF(Q30>0,"Yes",IF(OR((O30+P30<50000),O30<23900,P30<26730),"Yes","No")) -> Yes
A31: 45655 | B31: 24700 | C31: 22690 | D31: 23330 | E31: 25830 | F31: 30880 | G31: 10430 | H31: 26890 | I31: 28170 | J31: 15410 | K31: 28540 | L31: =SUM(B31:K31) -> 236870 | M31: 243056.9 | N31: =IF(OR(O31<24300,P31<25700),MAX(L31,M31),L31) -> 243056.9 | O31: 21155 | P31: 21130 | Q31: 0 | R31: =IF(Q31>0,"Yes",IF(OR((O31+P31<50000),O31<23900,P31<26730),"Yes","No")) -> Yes
A32: 45656 | B32: 23130 | C32: 21350 | D32: 22620 | E32: 24240 | F32: 29580 | G32: 9970 | H32: 25480 | I32: 28170 | J32: 14590 | K32: 28540 | L32: =SUM(B32:K32) -> 227670 | M32: 253128.84 | N32: =IF(OR(O32<24300,P32<25700),MAX(L32,M32),L32) -> 253128.84 | O32: 21155 | P32: 26730 | Q32: 0 | R32: =IF(Q32>0,"Yes",IF(OR((O32+P32<50000),O32<23900,P32<26730),"Yes","No")) -> Yes
A33: 45657 | B33: 18550 | C33: 17680 | D33: 17640 | E33: 19940 | F33: 22910 | G33: 23600 | H33: 20390 | I33: 28170 | J33: 10960 | K33: 28540 | L33: =SUM(B33:K33) -> 208380 | M33: 209439.86 | N33: =IF(OR(O33<24300,P33<25700),MAX(L33,M33),L33) -> 209439.86 | O33: 21155 | P33: 26730 | Q33: 609 | R33: =IF(Q33>0,"Yes",IF(OR((O33+P33<50000),O33<23900,P33<26730),"Yes","No")) -> Yes
A34: 45658 | B34: 15560 | C34: 16150 | D34: 14460 | E34: 18130 | F34: 19240 | G34: 19610 | H34: 16680 | I34: 16770 | J34: 9660 | K34: 16970 | L34: =SUM(B34:K34) -> 163230 | M34: 159331.83 | N34: =IF(OR(O34<24300,P34<25700),MAX(L34,M34),L34) -> 163230 | O34: 10284 | P34: 23852 | Q34: 0 | R34: =IF(Q34>0,"Yes",IF(OR((O34+P34<50000),O34<23900,P34<26730),"Yes","No")) -> Yes
A35: 45659 | B35: 2080 | C35: 2180 | D35: 1970 | E35: 2470 | F35: 2580 | G35: 8580 | H35: 8240 | I35: 8170 | J35: 4780 | K35: 8330 | L35: =SUM(B35:K35) -> 49380 | M35: 65603.392 | N35: =IF(OR(O35<24300,P35<25700),MAX(L35,M35),L35) -> 65603.392 | O35: 24020 | P35: 26730 | Q35: 23665 | R35: =IF(Q35>0,"Yes",IF(OR((O35+P35<50000),O35<23900,P35<26730),"Yes","No")) -> Yes
A36: 45660 | B36: 22450 | C36: 23350 | D36: 21290 | E36: 26210 | F36: 27410 | G36: 31720 | H36: 26720 | I36: 26420 | J36: 15080 | K36: 27070 | L36: =SUM(B36:K36) -> 247720 | M36: 200975.18 | N36: =IF(OR(O36<24300,P36<25700),MAX(L36,M36),L36) -> 247720 | O36: 23987 | P36: 26730 | Q36: 0 | R36: =IF(Q36>0,"Yes",IF(OR((O36+P36<50000),O36<23900,P36<26730),"Yes","No")) -> No
A37: 45661 | B37: 16810 | C37: 17690 | D37: 15850 | E37: 19950 | F37: 20720 | G37: 21130 | H37: 18110 | I37: 17770 | J37: 10140 | K37: 18550 | L37: =SUM(B37:K37) -> 176720 | M37: 180737.76 | N37: =IF(OR(O37<24300,P37<25700),MAX(L37,M37),L37) -> 180737.76 | O37: 23987 | P37: 26730 | Q37: 0 | R37: =IF(Q37>0,"Yes",IF(OR((O37+P37<50000),O37<23900,P37<26730),"Yes","No")) -> No
A38: 45662 | B38: 20000 | C38: 23080 | D38: 21080 | E38: 26210 | F38: 28100 | G38: 28760 | H38: 24750 | I38: 25210 | J38: 15790 | K38: 26830 | L38: =SUM(B38:K38) -> 239810 | M38: 251611.29 | N38: =IF(OR(O38<24300,P38<25700),MAX(L38,M38),L38) -> 239810 | O38: 24786 | P38: 26730 | Q38: 729 | R38: =IF(Q38>0,"Yes",IF(OR((O38+P38<50000),O38<23900,P38<26730),"Yes","No")) -> Yes
A39: 45663 | B39: 24820 | C39: 26340 | D39: 23580 | E39: 29960 | F39: 30760 | G39: 32830 | H39: 27920 | I39: 27020 | J39: 15420 | K39: 27100 | L39: =SUM(B39:K39) -> 265750 | M39: 204531.44 | N39: =IF(OR(O39<24300,P39<25700),MAX(L39,M39),L39) -> 265750 | O39: 23987 | P39: 26730 | Q39: 0 | R39: =IF(Q39>0,"Yes",IF(OR((O39+P39<50000),O39<23900,P39<26730),"Yes","No")) -> No
A40: 45664 | B40: 18210 | C40: 19070 | D40: 16890 | E40: 21300 | F40: 21990 | G40: 22160 | H40: 18510 | I40: 18620 | J40: 11040 | K40: 19350 | L40: =SUM(B40:K40) -> 187140 | M40: 202547.68 | N40: =IF(OR(O40<24300,P40<25700),MAX(L40,M40),L40) -> 187140 | O40: 24786 | P40: 26730 | Q40: 0 | R40: =IF(Q40>0,"Yes",IF(OR((O40+P40<50000),O40<23900,P40<26730),"Yes","No")) -> No
A41: 45665 | B41: 13370 | C41: 13970 | D41: 12630 | E41: 15820 | F41: 16500 | G41: 16740 | H41: 14160 | I41: 14020 | J41: 8040 | K41: 14060 | L41: =SUM(B41:K41) -> 139310 | M41: 132361.08 | N41: =IF(OR(O41<24300,P41<25700),MAX(L41,M41),L41) -> 139310 | O41: 24786 | P41: 26730 | Q41: 0 | R41: =IF(Q41>0,"Yes",IF(OR((O41+P41<50000),O41<23900,P41<26730),"Yes","No")) -> No
... A135: 45759 | B135: 4270 | C135: 3700 | D135: 3670 | E135: 4390 | F135: 4750 | G135: 35560 | H135: 29730 | I135: 29850 | J135: 35500 | K135: 30640 | L135: =SUM(B135:K135) -> 182060 | M135: 301616.36 | N135: =IF(OR(O135<24300,P135<25700),MAX(L135,M135),L135) -> 301616.36 | O135: 5834 | P135: 24368 | Q135: 125132 | R135: =IF(Q135>0,"Yes",IF(OR((O135+P135<50000),O135<23900,P135<26730),"Yes","No")) -> Yes
...

Sheet Sheet2
A1: Date | B1: Energy (kWh) | C1: GHI | D1: SY | E1: PR | F1: Availability | G1: OG1 | H1: OG2 | I1: OG3 | J1: OG4 | K1: OG5 | L1: Total Meter Generation (kWh) | M1: PAE Energy (kWh) | N1: Curtailed Energy (kWh) | O1: Generation (kWh) | P1: Corrected Meter Generation (kWh) | Q1: STS1 | R1: STS2 | S1: STS3 | T1: STS4 | U1: STS5 | V1: STS6 | W1: STS7 | X1: STS8 | Y1: STS9 | Z1: STS10 | AA1: Total STS Generation (kWh) | AB1: Corrected STS Generation (kWh) | AC1: Auxiliary Energy (kWh) | AD1: STS12 | AE1: STS22 | AF1: STS32 | AG1: STS42 | AH1: STS52 | AI1: STS62 | AJ1: STS72 | AK1: STS82 | AL1: STS92 | AM1: STS102 | AN1: MTR-STS Ratio (Mtr/Inv) | AO1: Daily Specific Yield | AP1: WS01 | AQ1: WS02 | AR1: WS03 | AS1: WS04 | AT1: WS05 | AU1: Average GHI | AV1: Plant Performance Ratio (PR) | AW1: Corrected Plant PR | AX1: System Availability (%) | AY1: PV Capacity (kWp) | AZ1: AC Capacity | BA1: Busbar 1 (STS 1 - 5) | BB1: Busbar 2 (STS 6 - 10) | BC1: Special remarks (any event happened causing low Performance?)
A2: 45688 | B2: 244325.41 | C2: 4.2064516 | D2: 3.4480284 | E2: 0.8197 | F2: 0.99 | G2: 56274.5 | H2: 0 | I2: 25059.37 | J2: 38917.74 | K2: 44454 | L2: 164705.61 | M2: 212112.5 | N2: 47406.89 | O2: 212112.5 | P2: 212112.5 | Q2: 18110 | R2: 18400 | S2: 3850 | T2: 3970 | U2: 3990 | V2: 19760 | W2: 16790 | X2: 16820 | Y2: 9750 | Z2: 17250 | AA2: 128690 | AB2: 176096.89 | AC2: 1380.38 | AD2: 0.8491 | AE2: 0.8624 | AF2: 0.2018 | AG2: 0.164 | AH2: 0.1684 | AI2: 0.7628 | AJ2: 0.785 | AK2: 0.749 | AL2: 0.784 | AM2: 0.7747 | AN2: 0.78133343 | AO2: 3.139152 | AP2: 3.15 | AQ2: 3.11 | AR2: 3.24 | AS2: 3.18 | AT2: 3.16 | AU2: 3.168 | AV2: 0.6101 | AW2: 0.99089394 | AX2: 0.998 | AY2: 67570 | AZ2: 53692 | BA2: 11900 | BB2: 26730 | BC2: - There is a power limitation on STS3, STS4 and STS5. - There is a power limitation on the STS6-STS10 because only one feeder line is available
A3: 45687 | B3: 244325.41 | C3: 4.2064516 | D3: 3.4480284 | E3: 0.8197 | F3: 0.99 | G3: 47274 | H3: 0 | I3: 39988.37 | J3: 14003.26 | K3: 43371 | L3: 144636.63 | M3: 173235.33 | N3: 28598.7 | O3: 173235.33 | P3: 173235.33 | Q3: 19520 | R3: 19480 | S3: 4010 | T3: 4130 | U3: 4140 | V3: 24280 | W3: 20810 | X3: 20570 | Y3: 11860 | Z3: 21450 | AA3: 150250 | AB3: 178848.7 | AC3: 1328.37 | AD3: 0.8685 | AE3: 0.8668 | AF3: 0.2032 | AG3: 0.1646 | AH3: 0.1661 | AI3: 0.9288 | AJ3: 0.9397 | AK3: 0.9076 | AL3: 0.9211 | AM3: 0.9307 | AN3: 1.0388102 | AO3: 2.5637906 | AP3: 3.26 | AQ3: 3.27 | AR3: 3.27 | AS3: 3.29 | AT3: 3.33 | AU3: 3.284 | AV3: 0.6897 | AW3: 0.78069141 | AX3: 0.998 | AY3: 67570 | AZ3: 53692 | BA3: 11900 | BB3: 11900 | BC3: - There is a power limitation on STS3, STS4 and STS5 - Request outage OG.4 NST.2 due to Relocation of Medium Voltage Cable Line (SKTM) affected by the KIPP Project and Rest Poll Jumper Configuration
A4: 45686 | B4: 244325.41 | C4: 4.2064516 | D4: 3.4480284 | E4: 0.8197 | F4: 0.99 | G4: 36207.5 | H4: 0 | I4: 13821.255 | J4: 30329.12 | K4: 22996 | L4: 103353.88 | M4: 101943.5 | N4: 0 | O4: 103353.88 | P4: 103353.88 | Q4: 12510 | R4: 12470 | S4: 4290 | T4: 4370 | U4: 4370 | V4: 15510 | W4: 13170 | X4: 13060 | Y4: 7450 | Z4: 13590 | AA4: 100790 | AB4: 100790 | AC4: 1438.9 | AD4: 0.9171 | AE4: 0.9146 | AF4: 0.359 | AG4: 0.288 | AH4: 0.2898 | AI4: 0.9798 | AJ4: 0.9892 | AK4: 0.9519 | AL4: 0.962 | AM4: 0.9807 | AN4: 0.97519324 | AO4: 1.5295823 | AP4: 1.96 | AQ4: 1.98 | AR4: 1.98 | AS4: 1.99 | AT4: 2.02 | AU4: 1.986 | AV4: 0.7632 | AW4: 0.77018242 | AX4: 0.998 | AY4: 67570 | AZ4: 53692 | BA4: 11900 | BB4: 25411 | BC4: There is a power limitation on STS3, STS4 and STS5
A5: 45685 | B5: 244325.41 | C5: 4.2064516 | D5: 3.4480284 | E5: 0.8197 | F5: 0.99 | G5: 32969.5 | H5: 0 | I5: 24176.875 | J5: 34210.25 | K5: 27011 | L5: 118367.62 | M5: 143367.17 | N5: 24999.545 | O5: 143367.17 | P5: 143367.17 | Q5: 13140 | R5: 13000 | S5: 3100 | T5: 3180 | U5: 3190 | V5: 21180 | W5: 18200 | X5: 17910 | Y5: 10370 | Z5: 18710 | AA5: 121980 | AB5: 146979.55 | AC5: 1314.88 | AD5: 0.678 | AE5: 0.6711 | AF5: 0.1793 | AG5: 0.145 | AH5: 0.148 | AI5: 0.9261 | AJ5: 0.9302 | AK5: 0.9036 | AL5: 0.9118 | AM5: 0.919 | AN5: 1.0305183 | AO5: 2.1217577 | AP5: 2.88 | AQ5: 2.83 | AR5: 2.86 | AS5: 2.88 | AT5: 2.87 | AU5: 2.864 | AV5: 0.6412 | AW5: 0.7408372 | AX5: 0.998 | AY5: 67570 | AZ5: 53692 | BA5: 11900 | BB5: 26730 | BC5: - There is a power limitation on STS3, STS4 and STS5 - Request outage OG.1 GSK.3 due to repair work of A3CS Medium Voltage Air Line (SUTM) cable that was detached from the insulator and fell into the traves
