Workbook
Name cfg_critical_below: Config!$C$4
Name cfg_high_below: Config!$C$5
Name cfg_medium_below: Config!$C$6
Name cfg_info_below: Config!$C$7
Name cfg_emit_normal: Config!$C$8
Name cfg_pstr_zero_threshold_kw: Config!$C$9
Name cfg_sibling_median_active_kw: Config!$C$10
Name cfg_min_active_siblings_pct: Config!$C$11
Name cfg_debounce_consecutive_steps: Config!$C$12
Name cfg_interval_minutes: Config!$C$13
Name cfg_pv_max: Config!$C$14
Name cfg_n_pv_total_in_workbook: Config!$C$15
Name cfg_poa_threshold_wm2: Config!$C$16
Name cfg_poa_floor_wm2: Config!$C$17
Name cfg_z_threshold: Config!$C$18
Name cfg_z_high_threshold: Config!$C$19
Name cfg_voc_ratio_threshold: Config!$C$20
Name cfg_stat_method: Config!$C$21
Name cfg_min_peer_strings: Config!$C$22
Name cfg_min_daylight_samples: Config!$C$23
Name cfg_i_clip_floor_a: Config!$C$24
Name cfg_i_threshold_a: Config!$C$25
Name cfg_min_voc_v: Config!$C$26
Name cfg_min_samples: Config!$C$27
Name cfg_hampel_window: Config!$C$28
Name cfg_hampel_max_deviation: Config!$C$29
Name cfg_enabled: Config!$C$30
Name cfg_default_source: Config!$C$31
Name panel_voc_stc_v: PanelSpec!$B$6
Name panel_vmp_stc_v: PanelSpec!$B$7
Name panel_imp_stc_a: PanelSpec!$B$8
Name panel_isc_stc_a: PanelSpec!$B$9
Name panel_pmax_stc_w: PanelSpec!$B$10
Name panel_voc_noct_v: PanelSpec!$B$11
Name panel_temp_coef_voc_pct_per_c: PanelSpec!$B$12
Name panel_temp_coef_pmax_pct_per_c: PanelSpec!$B$13
Name panel_temp_coef_isc_pct_per_c: PanelSpec!$B$14
Name panel_t_stc_c: PanelSpec!$B$15
Name panel_max_system_voltage_v: PanelSpec!$B$16
Name panel_default_modules_per_string: PanelSpec!$B$17
Name panel_modules_per_string_WB01: PanelSpec!$B$18
Name panel_modules_per_string_WB02: PanelSpec!$B$19
Name panel_modules_per_string_WB03_10: PanelSpec!$B$20
Name voc_per_module_calc: PanelSpec!$B$24
Name voc_string_24_calc: PanelSpec!$B$25
Name voc_string_26_calc: PanelSpec!$B$26
Name tcell_dummy_c: PanelSpec!$B$23
Name rstr_fleet_mean: M2b_PeerZScore!$B$15
Name rstr_fleet_median: M2b_PeerZScore!$B$16
Name rstr_fleet_std: M2b_PeerZScore!$B$17

Sheet README
A1: M2 PV Performance — Workbook Excel
A2: Reverse engineering dari pv_pipeline/ (notebook 20260514stringmap_v1.5.ipynb)
A4: Iterasi log
A5: Iterasi | B5: Tanggal | C5: Detector | D5: Sheet yang ditambah
A6: 1 (Phase 1) | B6: 2026-05-28 | C6: — | D6: Hanya dokumen overview (.docx + .md). Belum ada Excel.
A7: 2 | B7: 2026-05-28 | C7: M2eAvailability | D7: README, Config, Raw_Data, EmptyPVMap, Helpers_M2e, M2e_Availability, M2e_AllStrings, Findings_Summary
A8: 3 | B8: 2026-05-28 | C8: M2bPeerZScore | D8: Meteo_Dummy, PanelSpec, Raw_Data_M2b, Helpers_M2b, M2b_PeerZScore, M2b_StringStatus, Hampel_Preprocessing, M2b_StatComparison
A10: Cara membaca
A11: • Sheet 'Config' adalah single source of truth untuk semua threshold. Edit di sini → seluruh workbook recalc.
A12: • Sheet 'Raw_Data' berisi data dummy realistis. Ganti dengan data aktual mu (paste over) untuk pakai workbook ini di lapangan.
A13: • Sheet 'Helpers_M2e' adalah JEMBATAN antara Raw_Data dan M2e_Availability. Tiap kolom punya formula yang ekuivalen dengan satu langkah di pv_pipeline/availability.py.
A14: • Sheet 'M2e_Availability' menampilkan hasil akhir per inverter & per string + severity. Sheet 'M2e_AllStrings' mereplika output sheet xlsx Python.
A15: • Severity dihitung via IFS() dari uptime_pct ke threshold di Config.
A16: • Workbook ini akan TUMBUH per iterasi — sheet baru ditambah tanpa mengubah yang lama.

Sheet Config
A1: M2 Configuration (mirror config/m2_config.yaml)
A3: Section | B3: Key | C3: Value | D3: Unit / Notes
A4: m2e.severity | B4: critical_below | C4: 90 | D4: % uptime; < ini → CRITICAL
A5: m2e.severity | B5: high_below | C5: 95 | D5: % uptime; < ini → HIGH
A6: m2e.severity | B6: medium_below | C6: 97 | D6: % uptime; < ini → MEDIUM
A7: m2e.severity | B7: info_below | C7: 99 | D7: % uptime; < ini → INFO; ≥ ini → NORMAL
A8: m2e.severity | B8: emit_normal | C8: 0 | D8: 1=emit NORMAL findings, 0=skip
A9: m2e.string_proxy | B9: pstr_zero_threshold_kw | C9: 0.1 | D9: kW; PV power < ini → string dianggap mati
A10: m2e.string_proxy | B10: sibling_median_active_kw | C10: 1 | D10: kW; median sibling >= ini → timestamp 'produktif'
A11: m2e.string_proxy | B11: min_active_siblings_pct | C11: 50 | D11: %; minimum % sibling aktif → 'qualified' timestamp
A12: m2e.string_proxy | B12: debounce_consecutive_steps | C12: 2 | D12: step; run candidate >= ini → genuine event. DUMMY=2 (original spec). PRODUKSI IKN=20 (~1h40m persist).
A13: system | B13: interval_minutes | C13: 5 | D13: menit; median selisih Start Time (auto-detected, override saat dummy)
A14: system | B14: pv_max | C14: 28 | D14: PV string per inverter (hardcoded Huawei cap)
A15: system | B15: n_pv_total_in_workbook | C15: 5 | D15: PV string yang ada di sheet ini (PV1..PV5)
... A20: m2b | B20: voc_ratio_threshold | C20: 0.95 | D20: voc_actual/voc_string_nominal > ini → confirm high_R (spec 4.2.3)
A21: m2b | B21: stat_method | C21: median | D21: mean | median | both (z_primary picker)
A22: m2b | B22: min_peer_strings | C22: 3 | D22: min sibling per inverter untuk valid peer comparison
A23: m2b | B23: min_daylight_samples | C23: 10 | D23: min samples lulus POA gate per inverter
A24: m2b | B24: i_clip_floor_a | C24: 0.1 | D24: clip(lower=0.1A) untuk hindari divide-by-zero saat R=V/I
A25: voc_estimator | B25: i_threshold_a | C25: 0.5 | D25: I < ini → dianggap open-circuit (sunrise/sunset)
A26: voc_estimator | B26: min_voc_v | C26: 10 | D26: V > ini → buang zero-reading sample
A27: voc_estimator | B27: min_samples | C27: 3 | D27: minimum samples valid untuk median voc
A28: preprocessing | B28: hampel_window | C28: 15 | D28: samples; rolling window (75 menit @ 5-min)
A29: preprocessing | B29: hampel_max_deviation | C29: 3 | D29: MAD-sigma; |x - median| / MAD > ini → outlier
A30: preprocessing | B30: enabled | C30: 0 | D30: 1=apply Hampel cleaning, 0=skip (raw V/I)
A31: poa | B31: default_source | C31: pyranometer_avg | D31: single source di dummy (production: 5 sources)

Sheet Raw_Data
A1: Raw_Data (dummy realistis — 2 inverter × 12 timestep)
A2: Skenario: INV01 punya PV3 fault 6-timestep; INV02 down 4-timestep. PV5 (kedua inverter) ada di EmptyPVMap.
A4: Inverter_ID | B4: Start Time | C4: Inverter status | D4: PV1 Power(kW) | E4: PV2 Power(kW) | F4: PV3 Power(kW) | G4: PV4 Power(kW) | H4: PV5 Power(kW)
A5: WB02-INV01 | B5: 46156.417 | C5: Grid connected | D5: 5 | E5: 4.9 | F5: 5.1 | G5: 5 | H5: 0
A6: WB02-INV01 | B6: 46156.42 | C6: Grid connected | D6: 5.05 | E6: 4.94 | F6: 5.1 | G6: 5.03 | H6: 0
A7: WB02-INV01 | B7: 46156.424 | C7: Grid connected | D7: 5.1 | E7: 4.98 | F7: 5.1 | G7: 5.06 | H7: 0
A8: WB02-INV01 | B8: 46156.427 | C8: Grid connected | D8: 5.15 | E8: 5.02 | F8: 0 | G8: 5 | H8: 0
A9: WB02-INV01 | B9: 46156.431 | C9: Grid connected | D9: 5 | E9: 5.06 | F9: 0 | G9: 5.03 | H9: 0
A10: WB02-INV01 | B10: 46156.434 | C10: Grid connected | D10: 5.05 | E10: 4.9 | F10: 0 | G10: 5.06 | H10: 0
A11: WB02-INV01 | B11: 46156.438 | C11: Grid connected | D11: 5.1 | E11: 4.94 | F11: 0 | G11: 5 | H11: 0
A12: WB02-INV01 | B12: 46156.441 | C12: Grid connected | D12: 5.15 | E12: 4.98 | F12: 0 | G12: 5.03 | H12: 0
A13: WB02-INV01 | B13: 46156.444 | C13: Grid connected | D13: 5 | E13: 5.02 | F13: 0 | G13: 5.06 | H13: 0
A14: WB02-INV01 | B14: 46156.448 | C14: Grid connected | D14: 5.05 | E14: 5.06 | F14: 5.1 | G14: 5 | H14: 0
A15: WB02-INV01 | B15: 46156.451 | C15: Grid connected | D15: 5.1 | E15: 4.9 | F15: 5.1 | G15: 5.03 | H15: 0
A16: WB02-INV01 | B16: 46156.455 | C16: Grid connected | D16: 5.15 | E16: 4.94 | F16: 5.1 | G16: 5.06 | H16: 0
... A28: WB02-INV02 | B28: 46156.455 | C28: Grid connected | D28: 5 | E28: 5 | F28: 5 | G28: 5 | H28: 0

Sheet EmptyPVMap
A1: EmptyPVMap — slot PV yang fisik tidak terpasang (skip dari peer comparison)
A2: Replica config/strings.yaml (245 inverter dalam file aktual). Di sini hanya entry yang relevan untuk dummy.
A4: Inverter_ID | B4: Empty PV indices (CSV) | C4: Note
A5: WB02-INV01 | B5: 5 | C5: DEMO: PV5 EMPTY by design
A6: WB02-INV02 | B6: 5 | C6: DEMO: PV5 EMPTY by design
A7: WB01-INV01 | B7: 19,20,21,22,23,24,25,26,27,28 | C7: Pola WB01 produksi (PV19-28 kosong)
A8: WB03-INV01 | C8: (contoh: tidak ada slot kosong)
A9: WB05-INV05 | B9: 5 | C9: DEMO M2b: PV5 EMPTY

Sheet Helpers_M2e
A1: Helpers_M2e — derived columns dari Raw_Data (per-row formulas)
A2: Setiap kolom = 1 langkah di pv_pipeline/availability.py. Edit Raw_Data → recalc otomatis.
A4: Inverter_ID | B4: Start Time | C4: status_raw | D4: _status_class | E4: sib_median_kW | F4: active_count | G4: active_pct | H4: qualified | I4: is_on | J4: cand_PV1 | K4: run_id_PV1 | L4: run_len_PV1 | M4: in_event_PV1 | N4: cand_PV2 | O4: run_id_PV2 | P4: run_len_PV2 | Q4: in_event_PV2 | R4: cand_PV3 | S4: run_id_PV3 | T4: run_len_PV3 | U4: in_event_PV3 | V4: cand_PV4 | W4: run_id_PV4 | X4: run_len_PV4 | Y4: in_event_PV4 | Z4: cand_PV5 | AA4: run_id_PV5 | AB4: run_len_PV5 | AC4: in_event_PV5
A5: =Raw_Data!A5 | B5: =Raw_Data!B5 | C5: =Raw_Data!C5 | D5: =IF(ISNUMBER(SEARCH("shutdown",LOWER(C5)))+ISNUMBER(SEARCH("fault",LOWER(C5))),"DOWN",IF(ISNUMBER(SEARCH("grid connected",LOWER(C5)))+ISNUMBER(SEARCH("on-grid",LOWER(C5))),"ON",IF(ISNUMBER(SEARCH("standby",LOWER(C5)))+ISNUMBER(SEARCH("no sunlight",LOWER(C5))),"TRANSITIONAL","UNKNOWN"))) | E5: =MEDIAN(Raw_Data!D5:H5) | F5: =COUNTIF(Raw_Data!D5:H5, ">"&cfg_pstr_zero_threshold_kw) | G5: =100*F5/cfg_n_pv_total_in_workbook | H5: =IF(AND(E5>=cfg_sibling_median_active_kw, G5>=cfg_min_active_siblings_pct),1,0) | I5: =IF(D5="ON",1,0) | J5: =IF(AND(I5=1, H5=1, Raw_Data!D5<cfg_pstr_zero_threshold_kw),1,0) | K5: =IF(J5=1,1,0) | L5: =IF(J5=1,COUNTIFS($A$5:$A$28,A5,$K$5:$K$28,K5,$J$5:$J$28,1),0) | M5: =IF(AND(J5=1, L5>=cfg_debounce_consecutive_steps),1,0) | N5: =IF(AND(I5=1, H5=1, Raw_Data!E5<cfg_pstr_zero_threshold_kw),1,0) | O5: =IF(N5=1,1,0) | P5: =IF(N5=1,COUNTIFS($A$5:$A$28,A5,$O$5:$O$28,O5,$N$5:$N$28,1),0) | Q5: =IF(AND(N5=1, P5>=cfg_debounce_consecutive_steps),1,0) | R5: =IF(AND(I5=1, H5=1, Raw_Data!F5<cfg_pstr_zero_threshold_kw),1,0) | S5: =IF(R5=1,1,0) | T5: =IF(R5=1,COUNTIFS($A$5:$A$28,A5,$S$5:$S$28,S5,$R$5:$R$28,1),0) | U5: =IF(AND(R5=1, T5>=cfg_debounce_consecutive_steps),1,0) | V5: =IF(AND(I5=1, H5=1, Raw_Data!G5<cfg_pstr_zero_threshold_kw),1,0) | W5: =IF(V5=1,1,0) | X5: =IF(V5=1,COUNTIFS($A$5:$A$28,A5,$W$5:$W$28,W5,$V$5:$V$28,1),0) | Y5: =IF(AND(V5=1, X5>=cfg_debounce_consecutive_steps),1,0) | Z5: =IF(AND(I5=1, H5=1, Raw_Data!H5<cfg_pstr_zero_threshold_kw),1,0) | AA5: =IF(Z5=1,1,0) | AB5: =IF(Z5=1,COUNTIFS($A$5:$A$28,A5,$AA$5:$AA$28,AA5,$Z$5:$Z$28,1),0) | AC5: =IF(AND(Z5=1, AB5>=cfg_debounce_consecutive_steps),1,0)
A6: =Raw_Data!A6 | B6: =Raw_Data!B6 | C6: =Raw_Data!C6 | D6: =IF(ISNUMBER(SEARCH("shutdown",LOWER(C6)))+ISNUMBER(SEARCH("fault",LOWER(C6))),"DOWN",IF(ISNUMBER(SEARCH("grid connected",LOWER(C6)))+ISNUMBER(SEARCH("on-grid",LOWER(C6))),"ON",IF(ISNUMBER(SEARCH("standby",LOWER(C6)))+ISNUMBER(SEARCH("no sunlight",LOWER(C6))),"TRANSITIONAL","UNKNOWN"))) | E6: =MEDIAN(Raw_Data!D6:H6) | F6: =COUNTIF(Raw_Data!D6:H6, ">"&cfg_pstr_zero_threshold_kw) | G6: =100*F6/cfg_n_pv_total_in_workbook | H6: =IF(AND(E6>=cfg_sibling_median_active_kw, G6>=cfg_min_active_siblings_pct),1,0) | I6: =IF(D6="ON",1,0) | J6: =IF(AND(I6=1, H6=1, Raw_Data!D6<cfg_pstr_zero_threshold_kw),1,0) | K6: =IF(A6<>A5,IF(J6=1, MAX($K$5:K5)+1, 0),IF(AND(J6=1, J5=0), K5+1,IF(J6=1, K5, K5))) | L6: =IF(J6=1,COUNTIFS($A$5:$A$28,A6,$K$5:$K$28,K6,$J$5:$J$28,1),0) | M6: =IF(AND(J6=1, L6>=cfg_debounce_consecutive_steps),1,0) | N6: =IF(AND(I6=1, H6=1, Raw_Data!E6<cfg_pstr_zero_threshold_kw),1,0) | O6: =IF(A6<>A5,IF(N6=1, MAX($O$5:O5)+1, 0),IF(AND(N6=1, N5=0), O5+1,IF(N6=1, O5, O5))) | P6: =IF(N6=1,COUNTIFS($A$5:$A$28,A6,$O$5:$O$28,O6,$N$5:$N$28,1),0) | Q6: =IF(AND(N6=1, P6>=cfg_debounce_consecutive_steps),1,0) | R6: =IF(AND(I6=1, H6=1, Raw_Data!F6<cfg_pstr_zero_threshold_kw),1,0) | S6: =IF(A6<>A5,IF(R6=1, MAX($S$5:S5)+1, 0),IF(AND(R6=1, R5=0), S5+1,IF(R6=1, S5, S5))) | T6: =IF(R6=1,COUNTIFS($A$5:$A$28,A6,$S$5:$S$28,S6,$R$5:$R$28,1),0) | U6: =IF(AND(R6=1, T6>=cfg_debounce_consecutive_steps),1,0) | V6: =IF(AND(I6=1, H6=1, Raw_Data!G6<cfg_pstr_zero_threshold_kw),1,0) | W6: =IF(A6<>A5,IF(V6=1, MAX($W$5:W5)+1, 0),IF(AND(V6=1, V5=0), W5+1,IF(V6=1, W5, W5))) | X6: =IF(V6=1,COUNTIFS($A$5:$A$28,A6,$W$5:$W$28,W6,$V$5:$V$28,1),0) | Y6: =IF(AND(V6=1, X6>=cfg_debounce_consecutive_steps),1,0) | Z6: =IF(AND(I6=1, H6=1, Raw_Data!H6<cfg_pstr_zero_threshold_kw),1,0) | AA6: =IF(A6<>A5,IF(Z6=1, MAX($AA$5:AA5)+1, 0),IF(AND(Z6=1, Z5=0), AA5+1,IF(Z6=1, AA5, AA5))) | AB6: =IF(Z6=1,COUNTIFS($A$5:$A$28,A6,$AA$5:$AA$28,AA6,$Z$5:$Z$28,1),0) | AC6: =IF(AND(Z6=1, AB6>=cfg_debounce_consecutive_steps),1,0)
A7: =Raw_Data!A7 | B7: =Raw_Data!B7 | C7: =Raw_Data!C7 | D7: =IF(ISNUMBER(SEARCH("shutdown",LOWER(C7)))+ISNUMBER(SEARCH("fault",LOWER(C7))),"DOWN",IF(ISNUMBER(SEARCH("grid connected",LOWER(C7)))+ISNUMBER(SEARCH("on-grid",LOWER(C7))),"ON",IF(ISNUMBER(SEARCH("standby",LOWER(C7)))+ISNUMBER(SEARCH("no sunlight",LOWER(C7))),"TRANSITIONAL","UNKNOWN"))) | E7: =MEDIAN(Raw_Data!D7:H7) | F7: =COUNTIF(Raw_Data!D7:H7, ">"&cfg_pstr_zero_threshold_kw) | G7: =100*F7/cfg_n_pv_total_in_workbook | H7: =IF(AND(E7>=cfg_sibling_median_active_kw, G7>=cfg_min_active_siblings_pct),1,0) | I7: =IF(D7="ON",1,0) | J7: =IF(AND(I7=1, H7=1, Raw_Data!D7<cfg_pstr_zero_threshold_kw),1,0) | K7: =IF(A7<>A6,IF(J7=1, MAX($K$5:K6)+1, 0),IF(AND(J7=1, J6=0), K6+1,IF(J7=1, K6, K6))) | L7: =IF(J7=1,COUNTIFS($A$5:$A$28,A7,$K$5:$K$28,K7,$J$5:$J$28,1),0) | M7: =IF(AND(J7=1, L7>=cfg_debounce_consecutive_steps),1,0) | N7: =IF(AND(I7=1, H7=1, Raw_Data!E7<cfg_pstr_zero_threshold_kw),1,0) | O7: =IF(A7<>A6,IF(N7=1, MAX($O$5:O6)+1, 0),IF(AND(N7=1, N6=0), O6+1,IF(N7=1, O6, O6))) | P7: =IF(N7=1,COUNTIFS($A$5:$A$28,A7,$O$5:$O$28,O7,$N$5:$N$28,1),0) | Q7: =IF(AND(N7=1, P7>=cfg_debounce_consecutive_steps),1,0) | R7: =IF(AND(I7=1, H7=1, Raw_Data!F7<cfg_pstr_zero_threshold_kw),1,0) | S7: =IF(A7<>A6,IF(R7=1, MAX($S$5:S6)+1, 0),IF(AND(R7=1, R6=0), S6+1,IF(R7=1, S6, S6))) | T7: =IF(R7=1,COUNTIFS($A$5:$A$28,A7,$S$5:$S$28,S7,$R$5:$R$28,1),0) | U7: =IF(AND(R7=1, T7>=cfg_debounce_consecutive_steps),1,0) | V7: =IF(AND(I7=1, H7=1, Raw_Data!G7<cfg_pstr_zero_threshold_kw),1,0) | W7: =IF(A7<>A6,IF(V7=1, MAX($W$5:W6)+1, 0),IF(AND(V7=1, V6=0), W6+1,IF(V7=1, W6, W6))) | X7: =IF(V7=1,COUNTIFS($A$5:$A$28,A7,$W$5:$W$28,W7,$V$5:$V$28,1),0) | Y7: =IF(AND(V7=1, X7>=cfg_debounce_consecutive_steps),1,0) | Z7: =IF(AND(I7=1, H7=1, Raw_Data!H7<cfg_pstr_zero_threshold_kw),1,0) | AA7: =IF(A7<>A6,IF(Z7=1, MAX($AA$5:AA6)+1, 0),IF(AND(Z7=1, Z6=0), AA6+1,IF(Z7=1, AA6, AA6))) | AB7: =IF(Z7=1,COUNTIFS($A$5:$A$28,A7,$AA$5:$AA$28,AA7,$Z$5:$Z$28,1),0) | AC7: =IF(AND(Z7=1, AB7>=cfg_debounce_consecutive_steps),1,0)
A8: =Raw_Data!A8 | B8: =Raw_Data!B8 | C8: =Raw_Data!C8 | D8: =IF(ISNUMBER(SEARCH("shutdown",LOWER(C8)))+ISNUMBER(SEARCH("fault",LOWER(C8))),"DOWN",IF(ISNUMBER(SEARCH("grid connected",LOWER(C8)))+ISNUMBER(SEARCH("on-grid",LOWER(C8))),"ON",IF(ISNUMBER(SEARCH("standby",LOWER(C8)))+ISNUMBER(SEARCH("no sunlight",LOWER(C8))),"TRANSITIONAL","UNKNOWN"))) | E8: =MEDIAN(Raw_Data!D8:H8) | F8: =COUNTIF(Raw_Data!D8:H8, ">"&cfg_pstr_zero_threshold_kw) | G8: =100*F8/cfg_n_pv_total_in_workbook | H8: =IF(AND(E8>=cfg_sibling_median_active_kw, G8>=cfg_min_active_siblings_pct),1,0) | I8: =IF(D8="ON",1,0) | J8: =IF(AND(I8=1, H8=1, Raw_Data!D8<cfg_pstr_zero_threshold_kw),1,0) | K8: =IF(A8<>A7,IF(J8=1, MAX($K$5:K7)+1, 0),IF(AND(J8=1, J7=0), K7+1,IF(J8=1, K7, K7))) | L8: =IF(J8=1,COUNTIFS($A$5:$A$28,A8,$K$5:$K$28,K8,$J$5:$J$28,1),0) | M8: =IF(AND(J8=1, L8>=cfg_debounce_consecutive_steps),1,0) | N8: =IF(AND(I8=1, H8=1, Raw_Data!E8<cfg_pstr_zero_threshold_kw),1,0) | O8: =IF(A8<>A7,IF(N8=1, MAX($O$5:O7)+1, 0),IF(AND(N8=1, N7=0), O7+1,IF(N8=1, O7, O7))) | P8: =IF(N8=1,COUNTIFS($A$5:$A$28,A8,$O$5:$O$28,O8,$N$5:$N$28,1),0) | Q8: =IF(AND(N8=1, P8>=cfg_debounce_consecutive_steps),1,0) | R8: =IF(AND(I8=1, H8=1, Raw_Data!F8<cfg_pstr_zero_threshold_kw),1,0) | S8: =IF(A8<>A7,IF(R8=1, MAX($S$5:S7)+1, 0),IF(AND(R8=1, R7=0), S7+1,IF(R8=1, S7, S7))) | T8: =IF(R8=1,COUNTIFS($A$5:$A$28,A8,$S$5:$S$28,S8,$R$5:$R$28,1),0) | U8: =IF(AND(R8=1, T8>=cfg_debounce_consecutive_steps),1,0) | V8: =IF(AND(I8=1, H8=1, Raw_Data!G8<cfg_pstr_zero_threshold_kw),1,0) | W8: =IF(A8<>A7,IF(V8=1, MAX($W$5:W7)+1, 0),IF(AND(V8=1, V7=0), W7+1,IF(V8=1, W7, W7))) | X8: =IF(V8=1,COUNTIFS($A$5:$A$28,A8,$W$5:$W$28,W8,$V$5:$V$28,1),0) | Y8: =IF(AND(V8=1, X8>=cfg_debounce_consecutive_steps),1,0) | Z8: =IF(AND(I8=1, H8=1, Raw_Data!H8<cfg_pstr_zero_threshold_kw),1,0) | AA8: =IF(A8<>A7,IF(Z8=1, MAX($AA$5:AA7)+1, 0),IF(AND(Z8=1, Z7=0), AA7+1,IF(Z8=1, AA7, AA7))) | AB8: =IF(Z8=1,COUNTIFS($A$5:$A$28,A8,$AA$5:$AA$28,AA8,$Z$5:$Z$28,1),0) | AC8: =IF(AND(Z8=1, AB8>=cfg_debounce_consecutive_steps),1,0)
A9: =Raw_Data!A9 | B9: =Raw_Data!B9 | C9: =Raw_Data!C9 | D9: =IF(ISNUMBER(SEARCH("shutdown",LOWER(C9)))+ISNUMBER(SEARCH("fault",LOWER(C9))),"DOWN",IF(ISNUMBER(SEARCH("grid connected",LOWER(C9)))+ISNUMBER(SEARCH("on-grid",LOWER(C9))),"ON",IF(ISNUMBER(SEARCH("standby",LOWER(C9)))+ISNUMBER(SEARCH("no sunlight",LOWER(C9))),"TRANSITIONAL","UNKNOWN"))) | E9: =MEDIAN(Raw_Data!D9:H9) | F9: =COUNTIF(Raw_Data!D9:H9, ">"&cfg_pstr_zero_threshold_kw) | G9: =100*F9/cfg_n_pv_total_in_workbook | H9: =IF(AND(E9>=cfg_sibling_median_active_kw, G9>=cfg_min_active_siblings_pct),1,0) | I9: =IF(D9="ON",1,0) | J9: =IF(AND(I9=1, H9=1, Raw_Data!D9<cfg_pstr_zero_threshold_kw),1,0) | K9: =IF(A9<>A8,IF(J9=1, MAX($K$5:K8)+1, 0),IF(AND(J9=1, J8=0), K8+1,IF(J9=1, K8, K8))) | L9: =IF(J9=1,COUNTIFS($A$5:$A$28,A9,$K$5:$K$28,K9,$J$5:$J$28,1),0) | M9: =IF(AND(J9=1, L9>=cfg_debounce_consecutive_steps),1,0) | N9: =IF(AND(I9=1, H9=1, Raw_Data!E9<cfg_pstr_zero_threshold_kw),1,0) | O9: =IF(A9<>A8,IF(N9=1, MAX($O$5:O8)+1, 0),IF(AND(N9=1, N8=0), O8+1,IF(N9=1, O8, O8))) | P9: =IF(N9=1,COUNTIFS($A$5:$A$28,A9,$O$5:$O$28,O9,$N$5:$N$28,1),0) | Q9: =IF(AND(N9=1, P9>=cfg_debounce_consecutive_steps),1,0) | R9: =IF(AND(I9=1, H9=1, Raw_Data!F9<cfg_pstr_zero_threshold_kw),1,0) | S9: =IF(A9<>A8,IF(R9=1, MAX($S$5:S8)+1, 0),IF(AND(R9=1, R8=0), S8+1,IF(R9=1, S8, S8))) | T9: =IF(R9=1,COUNTIFS($A$5:$A$28,A9,$S$5:$S$28,S9,$R$5:$R$28,1),0) | U9: =IF(AND(R9=1, T9>=cfg_debounce_consecutive_steps),1,0) | V9: =IF(AND(I9=1, H9=1, Raw_Data!G9<cfg_pstr_zero_threshold_kw),1,0) | W9: =IF(A9<>A8,IF(V9=1, MAX($W$5:W8)+1, 0),IF(AND(V9=1, V8=0), W8+1,IF(V9=1, W8, W8))) | X9: =IF(V9=1,COUNTIFS($A$5:$A$28,A9,$W$5:$W$28,W9,$V$5:$V$28,1),0) | Y9: =IF(AND(V9=1, X9>=cfg_debounce_consecutive_steps),1,0) | Z9: =IF(AND(I9=1, H9=1, Raw_Data!H9<cfg_pstr_zero_threshold_kw),1,0) | AA9: =IF(A9<>A8,IF(Z9=1, MAX($AA$5:AA8)+1, 0),IF(AND(Z9=1, Z8=0), AA8+1,IF(Z9=1, AA8, AA8))) | AB9: =IF(Z9=1,COUNTIFS($A$5:$A$28,A9,$AA$5:$AA$28,AA9,$Z$5:$Z$28,1),0) | AC9: =IF(AND(Z9=1, AB9>=cfg_debounce_consecutive_steps),1,0)
A10: =Raw_Data!A10 | B10: =Raw_Data!B10 | C10: =Raw_Data!C10 | D10: =IF(ISNUMBER(SEARCH("shutdown",LOWER(C10)))+ISNUMBER(SEARCH("fault",LOWER(C10))),"DOWN",IF(ISNUMBER(SEARCH("grid connected",LOWER(C10)))+ISNUMBER(SEARCH("on-grid",LOWER(C10))),"ON",IF(ISNUMBER(SEARCH("standby",LOWER(C10)))+ISNUMBER(SEARCH("no sunlight",LOWER(C10))),"TRANSITIONAL","UNKNOWN"))) | E10: =MEDIAN(Raw_Data!D10:H10) | F10: =COUNTIF(Raw_Data!D10:H10, ">"&cfg_pstr_zero_threshold_kw) | G10: =100*F10/cfg_n_pv_total_in_workbook | H10: =IF(AND(E10>=cfg_sibling_median_active_kw, G10>=cfg_min_active_siblings_pct),1,0) | I10: =IF(D10="ON",1,0) | J10: =IF(AND(I10=1, H10=1, Raw_Data!D10<cfg_pstr_zero_threshold_kw),1,0) | K10: =IF(A10<>A9,IF(J10=1, MAX($K$5:K9)+1, 0),IF(AND(J10=1, J9=0), K9+1,IF(J10=1, K9, K9))) | L10: =IF(J10=1,COUNTIFS($A$5:$A$28,A10,$K$5:$K$28,K10,$J$5:$J$28,1),0) | M10: =IF(AND(J10=1, L10>=cfg_debounce_consecutive_steps),1,0) | N10: =IF(AND(I10=1, H10=1, Raw_Data!E10<cfg_pstr_zero_threshold_kw),1,0) | O10: =IF(A10<>A9,IF(N10=1, MAX($O$5:O9)+1, 0),IF(AND(N10=1, N9=0), O9+1,IF(N10=1, O9, O9))) | P10: =IF(N10=1,COUNTIFS($A$5:$A$28,A10,$O$5:$O$28,O10,$N$5:$N$28,1),0) | Q10: =IF(AND(N10=1, P10>=cfg_debounce_consecutive_steps),1,0) | R10: =IF(AND(I10=1, H10=1, Raw_Data!F10<cfg_pstr_zero_threshold_kw),1,0) | S10: =IF(A10<>A9,IF(R10=1, MAX($S$5:S9)+1, 0),IF(AND(R10=1, R9=0), S9+1,IF(R10=1, S9, S9))) | T10: =IF(R10=1,COUNTIFS($A$5:$A$28,A10,$S$5:$S$28,S10,$R$5:$R$28,1),0) | U10: =IF(AND(R10=1, T10>=cfg_debounce_consecutive_steps),1,0) | V10: =IF(AND(I10=1, H10=1, Raw_Data!G10<cfg_pstr_zero_threshold_kw),1,0) | W10: =IF(A10<>A9,IF(V10=1, MAX($W$5:W9)+1, 0),IF(AND(V10=1, V9=0), W9+1,IF(V10=1, W9, W9))) | X10: =IF(V10=1,COUNTIFS($A$5:$A$28,A10,$W$5:$W$28,W10,$V$5:$V$28,1),0) | Y10: =IF(AND(V10=1, X10>=cfg_debounce_consecutive_steps),1,0) | Z10: =IF(AND(I10=1, H10=1, Raw_Data!H10<cfg_pstr_zero_threshold_kw),1,0) | AA10: =IF(A10<>A9,IF(Z10=1, MAX($AA$5:AA9)+1, 0),IF(AND(Z10=1, Z9=0), AA9+1,IF(Z10=1, AA9, AA9))) | AB10: =IF(Z10=1,COUNTIFS($A$5:$A$28,A10,$AA$5:$AA$28,AA10,$Z$5:$Z$28,1),0) | AC10: =IF(AND(Z10=1, AB10>=cfg_debounce_consecutive_steps),1,0)
A11: =Raw_Data!A11 | B11: =Raw_Data!B11 | C11: =Raw_Data!C11 | D11: =IF(ISNUMBER(SEARCH("shutdown",LOWER(C11)))+ISNUMBER(SEARCH("fault",LOWER(C11))),"DOWN",IF(ISNUMBER(SEARCH("grid connected",LOWER(C11)))+ISNUMBER(SEARCH("on-grid",LOWER(C11))),"ON",IF(ISNUMBER(SEARCH("standby",LOWER(C11)))+ISNUMBER(SEARCH("no sunlight",LOWER(C11))),"TRANSITIONAL","UNKNOWN"))) | E11: =MEDIAN(Raw_Data!D11:H11) | F11: =COUNTIF(Raw_Data!D11:H11, ">"&cfg_pstr_zero_threshold_kw) | G11: =100*F11/cfg_n_pv_total_in_workbook | H11: =IF(AND(E11>=cfg_sibling_median_active_kw, G11>=cfg_min_active_siblings_pct),1,0) | I11: =IF(D11="ON",1,0) | J11: =IF(AND(I11=1, H11=1, Raw_Data!D11<cfg_pstr_zero_threshold_kw),1,0) | K11: =IF(A11<>A10,IF(J11=1, MAX($K$5:K10)+1, 0),IF(AND(J11=1, J10=0), K10+1,IF(J11=1, K10, K10))) | L11: =IF(J11=1,COUNTIFS($A$5:$A$28,A11,$K$5:$K$28,K11,$J$5:$J$28,1),0) | M11: =IF(AND(J11=1, L11>=cfg_debounce_consecutive_steps),1,0) | N11: =IF(AND(I11=1, H11=1, Raw_Data!E11<cfg_pstr_zero_threshold_kw),1,0) | O11: =IF(A11<>A10,IF(N11=1, MAX($O$5:O10)+1, 0),IF(AND(N11=1, N10=0), O10+1,IF(N11=1, O10, O10))) | P11: =IF(N11=1,COUNTIFS($A$5:$A$28,A11,$O$5:$O$28,O11,$N$5:$N$28,1),0) | Q11: =IF(AND(N11=1, P11>=cfg_debounce_consecutive_steps),1,0) | R11: =IF(AND(I11=1, H11=1, Raw_Data!F11<cfg_pstr_zero_threshold_kw),1,0) | S11: =IF(A11<>A10,IF(R11=1, MAX($S$5:S10)+1, 0),IF(AND(R11=1, R10=0), S10+1,IF(R11=1, S10, S10))) | T11: =IF(R11=1,COUNTIFS($A$5:$A$28,A11,$S$5:$S$28,S11,$R$5:$R$28,1),0) | U11: =IF(AND(R11=1, T11>=cfg_debounce_consecutive_steps),1,0) | V11: =IF(AND(I11=1, H11=1, Raw_Data!G11<cfg_pstr_zero_threshold_kw),1,0) | W11: =IF(A11<>A10,IF(V11=1, MAX($W$5:W10)+1, 0),IF(AND(V11=1, V10=0), W10+1,IF(V11=1, W10, W10))) | X11: =IF(V11=1,COUNTIFS($A$5:$A$28,A11,$W$5:$W$28,W11,$V$5:$V$28,1),0) | Y11: =IF(AND(V11=1, X11>=cfg_debounce_consecutive_steps),1,0) | Z11: =IF(AND(I11=1, H11=1, Raw_Data!H11<cfg_pstr_zero_threshold_kw),1,0) | AA11: =IF(A11<>A10,IF(Z11=1, MAX($AA$5:AA10)+1, 0),IF(AND(Z11=1, Z10=0), AA10+1,IF(Z11=1, AA10, AA10))) | AB11: =IF(Z11=1,COUNTIFS($A$5:$A$28,A11,$AA$5:$AA$28,AA11,$Z$5:$Z$28,1),0) | AC11: =IF(AND(Z11=1, AB11>=cfg_debounce_consecutive_steps),1,0)
A12: =Raw_Data!A12 | B12: =Raw_Data!B12 | C12: =Raw_Data!C12 | D12: =IF(ISNUMBER(SEARCH("shutdown",LOWER(C12)))+ISNUMBER(SEARCH("fault",LOWER(C12))),"DOWN",IF(ISNUMBER(SEARCH("grid connected",LOWER(C12)))+ISNUMBER(SEARCH("on-grid",LOWER(C12))),"ON",IF(ISNUMBER(SEARCH("standby",LOWER(C12)))+ISNUMBER(SEARCH("no sunlight",LOWER(C12))),"TRANSITIONAL","UNKNOWN"))) | E12: =MEDIAN(Raw_Data!D12:H12) | F12: =COUNTIF(Raw_Data!D12:H12, ">"&cfg_pstr_zero_threshold_kw) | G12: =100*F12/cfg_n_pv_total_in_workbook | H12: =IF(AND(E12>=cfg_sibling_median_active_kw, G12>=cfg_min_active_siblings_pct),1,0) | I12: =IF(D12="ON",1,0) | J12: =IF(AND(I12=1, H12=1, Raw_Data!D12<cfg_pstr_zero_threshold_kw),1,0) | K12: =IF(A12<>A11,IF(J12=1, MAX($K$5:K11)+1, 0),IF(AND(J12=1, J11=0), K11+1,IF(J12=1, K11, K11))) | L12: =IF(J12=1,COUNTIFS($A$5:$A$28,A12,$K$5:$K$28,K12,$J$5:$J$28,1),0) | M12: =IF(AND(J12=1, L12>=cfg_debounce_consecutive_steps),1,0) | N12: =IF(AND(I12=1, H12=1, Raw_Data!E12<cfg_pstr_zero_threshold_kw),1,0) | O12: =IF(A12<>A11,IF(N12=1, MAX($O$5:O11)+1, 0),IF(AND(N12=1, N11=0), O11+1,IF(N12=1, O11, O11))) | P12: =IF(N12=1,COUNTIFS($A$5:$A$28,A12,$O$5:$O$28,O12,$N$5:$N$28,1),0) | Q12: =IF(AND(N12=1, P12>=cfg_debounce_consecutive_steps),1,0) | R12: =IF(AND(I12=1, H12=1, Raw_Data!F12<cfg_pstr_zero_threshold_kw),1,0) | S12: =IF(A12<>A11,IF(R12=1, MAX($S$5:S11)+1, 0),IF(AND(R12=1, R11=0), S11+1,IF(R12=1, S11, S11))) | T12: =IF(R12=1,COUNTIFS($A$5:$A$28,A12,$S$5:$S$28,S12,$R$5:$R$28,1),0) | U12: =IF(AND(R12=1, T12>=cfg_debounce_consecutive_steps),1,0) | V12: =IF(AND(I12=1, H12=1, Raw_Data!G12<cfg_pstr_zero_threshold_kw),1,0) | W12: =IF(A12<>A11,IF(V12=1, MAX($W$5:W11)+1, 0),IF(AND(V12=1, V11=0), W11+1,IF(V12=1, W11, W11))) | X12: =IF(V12=1,COUNTIFS($A$5:$A$28,A12,$W$5:$W$28,W12,$V$5:$V$28,1),0) | Y12: =IF(AND(V12=1, X12>=cfg_debounce_consecutive_steps),1,0) | Z12: =IF(AND(I12=1, H12=1, Raw_Data!H12<cfg_pstr_zero_threshold_kw),1,0) | AA12: =IF(A12<>A11,IF(Z12=1, MAX($AA$5:AA11)+1, 0),IF(AND(Z12=1, Z11=0), AA11+1,IF(Z12=1, AA11, AA11))) | AB12: =IF(Z12=1,COUNTIFS($A$5:$A$28,A12,$AA$5:$AA$28,AA12,$Z$5:$Z$28,1),0) | AC12: =IF(AND(Z12=1, AB12>=cfg_debounce_consecutive_steps),1,0)
A13: =Raw_Data!A13 | B13: =Raw_Data!B13 | C13: =Raw_Data!C13 | D13: =IF(ISNUMBER(SEARCH("shutdown",LOWER(C13)))+ISNUMBER(SEARCH("fault",LOWER(C13))),"DOWN",IF(ISNUMBER(SEARCH("grid connected",LOWER(C13)))+ISNUMBER(SEARCH("on-grid",LOWER(C13))),"ON",IF(ISNUMBER(SEARCH("standby",LOWER(C13)))+ISNUMBER(SEARCH("no sunlight",LOWER(C13))),"TRANSITIONAL","UNKNOWN"))) | E13: =MEDIAN(Raw_Data!D13:H13) | F13: =COUNTIF(Raw_Data!D13:H13, ">"&cfg_pstr_zero_threshold_kw) | G13: =100*F13/cfg_n_pv_total_in_workbook | H13: =IF(AND(E13>=cfg_sibling_median_active_kw, G13>=cfg_min_active_siblings_pct),1,0) | I13: =IF(D13="ON",1,0) | J13: =IF(AND(I13=1, H13=1, Raw_Data!D13<cfg_pstr_zero_threshold_kw),1,0) | K13: =IF(A13<>A12,IF(J13=1, MAX($K$5:K12)+1, 0),IF(AND(J13=1, J12=0), K12+1,IF(J13=1, K12, K12))) | L13: =IF(J13=1,COUNTIFS($A$5:$A$28,A13,$K$5:$K$28,K13,$J$5:$J$28,1),0) | M13: =IF(AND(J13=1, L13>=cfg_debounce_consecutive_steps),1,0) | N13: =IF(AND(I13=1, H13=1, Raw_Data!E13<cfg_pstr_zero_threshold_kw),1,0) | O13: =IF(A13<>A12,IF(N13=1, MAX($O$5:O12)+1, 0),IF(AND(N13=1, N12=0), O12+1,IF(N13=1, O12, O12))) | P13: =IF(N13=1,COUNTIFS($A$5:$A$28,A13,$O$5:$O$28,O13,$N$5:$N$28,1),0) | Q13: =IF(AND(N13=1, P13>=cfg_debounce_consecutive_steps),1,0) | R13: =IF(AND(I13=1, H13=1, Raw_Data!F13<cfg_pstr_zero_threshold_kw),1,0) | S13: =IF(A13<>A12,IF(R13=1, MAX($S$5:S12)+1, 0),IF(AND(R13=1, R12=0), S12+1,IF(R13=1, S12, S12))) | T13: =IF(R13=1,COUNTIFS($A$5:$A$28,A13,$S$5:$S$28,S13,$R$5:$R$28,1),0) | U13: =IF(AND(R13=1, T13>=cfg_debounce_consecutive_steps),1,0) | V13: =IF(AND(I13=1, H13=1, Raw_Data!G13<cfg_pstr_zero_threshold_kw),1,0) | W13: =IF(A13<>A12,IF(V13=1, MAX($W$5:W12)+1, 0),IF(AND(V13=1, V12=0), W12+1,IF(V13=1, W12, W12))) | X13: =IF(V13=1,COUNTIFS($A$5:$A$28,A13,$W$5:$W$28,W13,$V$5:$V$28,1),0) | Y13: =IF(AND(V13=1, X13>=cfg_debounce_consecutive_steps),1,0) | Z13: =IF(AND(I13=1, H13=1, Raw_Data!H13<cfg_pstr_zero_threshold_kw),1,0) | AA13: =IF(A13<>A12,IF(Z13=1, MAX($AA$5:AA12)+1, 0),IF(AND(Z13=1, Z12=0), AA12+1,IF(Z13=1, AA12, AA12))) | AB13: =IF(Z13=1,COUNTIFS($A$5:$A$28,A13,$AA$5:$AA$28,AA13,$Z$5:$Z$28,1),0) | AC13: =IF(AND(Z13=1, AB13>=cfg_debounce_consecutive_steps),1,0)
A14: =Raw_Data!A14 | B14: =Raw_Data!B14 | C14: =Raw_Data!C14 | D14: =IF(ISNUMBER(SEARCH("shutdown",LOWER(C14)))+ISNUMBER(SEARCH("fault",LOWER(C14))),"DOWN",IF(ISNUMBER(SEARCH("grid connected",LOWER(C14)))+ISNUMBER(SEARCH("on-grid",LOWER(C14))),"ON",IF(ISNUMBER(SEARCH("standby",LOWER(C14)))+ISNUMBER(SEARCH("no sunlight",LOWER(C14))),"TRANSITIONAL","UNKNOWN"))) | E14: =MEDIAN(Raw_Data!D14:H14) | F14: =COUNTIF(Raw_Data!D14:H14, ">"&cfg_pstr_zero_threshold_kw) | G14: =100*F14/cfg_n_pv_total_in_workbook | H14: =IF(AND(E14>=cfg_sibling_median_active_kw, G14>=cfg_min_active_siblings_pct),1,0) | I14: =IF(D14="ON",1,0) | J14: =IF(AND(I14=1, H14=1, Raw_Data!D14<cfg_pstr_zero_threshold_kw),1,0) | K14: =IF(A14<>A13,IF(J14=1, MAX($K$5:K13)+1, 0),IF(AND(J14=1, J13=0), K13+1,IF(J14=1, K13, K13))) | L14: =IF(J14=1,COUNTIFS($A$5:$A$28,A14,$K$5:$K$28,K14,$J$5:$J$28,1),0) | M14: =IF(AND(J14=1, L14>=cfg_debounce_consecutive_steps),1,0) | N14: =IF(AND(I14=1, H14=1, Raw_Data!E14<cfg_pstr_zero_threshold_kw),1,0) | O14: =IF(A14<>A13,IF(N14=1, MAX($O$5:O13)+1, 0),IF(AND(N14=1, N13=0), O13+1,IF(N14=1, O13, O13))) | P14: =IF(N14=1,COUNTIFS($A$5:$A$28,A14,$O$5:$O$28,O14,$N$5:$N$28,1),0) | Q14: =IF(AND(N14=1, P14>=cfg_debounce_consecutive_steps),1,0) | R14: =IF(AND(I14=1, H14=1, Raw_Data!F14<cfg_pstr_zero_threshold_kw),1,0) | S14: =IF(A14<>A13,IF(R14=1, MAX($S$5:S13)+1, 0),IF(AND(R14=1, R13=0), S13+1,IF(R14=1, S13, S13))) | T14: =IF(R14=1,COUNTIFS($A$5:$A$28,A14,$S$5:$S$28,S14,$R$5:$R$28,1),0) | U14: =IF(AND(R14=1, T14>=cfg_debounce_consecutive_steps),1,0) | V14: =IF(AND(I14=1, H14=1, Raw_Data!G14<cfg_pstr_zero_threshold_kw),1,0) | W14: =IF(A14<>A13,IF(V14=1, MAX($W$5:W13)+1, 0),IF(AND(V14=1, V13=0), W13+1,IF(V14=1, W13, W13))) | X14: =IF(V14=1,COUNTIFS($A$5:$A$28,A14,$W$5:$W$28,W14,$V$5:$V$28,1),0) | Y14: =IF(AND(V14=1, X14>=cfg_debounce_consecutive_steps),1,0) | Z14: =IF(AND(I14=1, H14=1, Raw_Data!H14<cfg_pstr_zero_threshold_kw),1,0) | AA14: =IF(A14<>A13,IF(Z14=1, MAX($AA$5:AA13)+1, 0),IF(AND(Z14=1, Z13=0), AA13+1,IF(Z14=1, AA13, AA13))) | AB14: =IF(Z14=1,COUNTIFS($A$5:$A$28,A14,$AA$5:$AA$28,AA14,$Z$5:$Z$28,1),0) | AC14: =IF(AND(Z14=1, AB14>=cfg_debounce_consecutive_steps),1,0)
A15: =Raw_Data!A15 | B15: =Raw_Data!B15 | C15: =Raw_Data!C15 | D15: =IF(ISNUMBER(SEARCH("shutdown",LOWER(C15)))+ISNUMBER(SEARCH("fault",LOWER(C15))),"DOWN",IF(ISNUMBER(SEARCH("grid connected",LOWER(C15)))+ISNUMBER(SEARCH("on-grid",LOWER(C15))),"ON",IF(ISNUMBER(SEARCH("standby",LOWER(C15)))+ISNUMBER(SEARCH("no sunlight",LOWER(C15))),"TRANSITIONAL","UNKNOWN"))) | E15: =MEDIAN(Raw_Data!D15:H15) | F15: =COUNTIF(Raw_Data!D15:H15, ">"&cfg_pstr_zero_threshold_kw) | G15: =100*F15/cfg_n_pv_total_in_workbook | H15: =IF(AND(E15>=cfg_sibling_median_active_kw, G15>=cfg_min_active_siblings_pct),1,0) | I15: =IF(D15="ON",1,0) | J15: =IF(AND(I15=1, H15=1, Raw_Data!D15<cfg_pstr_zero_threshold_kw),1,0) | K15: =IF(A15<>A14,IF(J15=1, MAX($K$5:K14)+1, 0),IF(AND(J15=1, J14=0), K14+1,IF(J15=1, K14, K14))) | L15: =IF(J15=1,COUNTIFS($A$5:$A$28,A15,$K$5:$K$28,K15,$J$5:$J$28,1),0) | M15: =IF(AND(J15=1, L15>=cfg_debounce_consecutive_steps),1,0) | N15: =IF(AND(I15=1, H15=1, Raw_Data!E15<cfg_pstr_zero_threshold_kw),1,0) | O15: =IF(A15<>A14,IF(N15=1, MAX($O$5:O14)+1, 0),IF(AND(N15=1, N14=0), O14+1,IF(N15=1, O14, O14))) | P15: =IF(N15=1,COUNTIFS($A$5:$A$28,A15,$O$5:$O$28,O15,$N$5:$N$28,1),0) | Q15: =IF(AND(N15=1, P15>=cfg_debounce_consecutive_steps),1,0) | R15: =IF(AND(I15=1, H15=1, Raw_Data!F15<cfg_pstr_zero_threshold_kw),1,0) | S15: =IF(A15<>A14,IF(R15=1, MAX($S$5:S14)+1, 0),IF(AND(R15=1, R14=0), S14+1,IF(R15=1, S14, S14))) | T15: =IF(R15=1,COUNTIFS($A$5:$A$28,A15,$S$5:$S$28,S15,$R$5:$R$28,1),0) | U15: =IF(AND(R15=1, T15>=cfg_debounce_consecutive_steps),1,0) | V15: =IF(AND(I15=1, H15=1, Raw_Data!G15<cfg_pstr_zero_threshold_kw),1,0) | W15: =IF(A15<>A14,IF(V15=1, MAX($W$5:W14)+1, 0),IF(AND(V15=1, V14=0), W14+1,IF(V15=1, W14, W14))) | X15: =IF(V15=1,COUNTIFS($A$5:$A$28,A15,$W$5:$W$28,W15,$V$5:$V$28,1),0) | Y15: =IF(AND(V15=1, X15>=cfg_debounce_consecutive_steps),1,0) | Z15: =IF(AND(I15=1, H15=1, Raw_Data!H15<cfg_pstr_zero_threshold_kw),1,0) | AA15: =IF(A15<>A14,IF(Z15=1, MAX($AA$5:AA14)+1, 0),IF(AND(Z15=1, Z14=0), AA14+1,IF(Z15=1, AA14, AA14))) | AB15: =IF(Z15=1,COUNTIFS($A$5:$A$28,A15,$AA$5:$AA$28,AA15,$Z$5:$Z$28,1),0) | AC15: =IF(AND(Z15=1, AB15>=cfg_debounce_consecutive_steps),1,0)
A16: =Raw_Data!A16 | B16: =Raw_Data!B16 | C16: =Raw_Data!C16 | D16: =IF(ISNUMBER(SEARCH("shutdown",LOWER(C16)))+ISNUMBER(SEARCH("fault",LOWER(C16))),"DOWN",IF(ISNUMBER(SEARCH("grid connected",LOWER(C16)))+ISNUMBER(SEARCH("on-grid",LOWER(C16))),"ON",IF(ISNUMBER(SEARCH("standby",LOWER(C16)))+ISNUMBER(SEARCH("no sunlight",LOWER(C16))),"TRANSITIONAL","UNKNOWN"))) | E16: =MEDIAN(Raw_Data!D16:H16) | F16: =COUNTIF(Raw_Data!D16:H16, ">"&cfg_pstr_zero_threshold_kw) | G16: =100*F16/cfg_n_pv_total_in_workbook | H16: =IF(AND(E16>=cfg_sibling_median_active_kw, G16>=cfg_min_active_siblings_pct),1,0) | I16: =IF(D16="ON",1,0) | J16: =IF(AND(I16=1, H16=1, Raw_Data!D16<cfg_pstr_zero_threshold_kw),1,0) | K16: =IF(A16<>A15,IF(J16=1, MAX($K$5:K15)+1, 0),IF(AND(J16=1, J15=0), K15+1,IF(J16=1, K15, K15))) | L16: =IF(J16=1,COUNTIFS($A$5:$A$28,A16,$K$5:$K$28,K16,$J$5:$J$28,1),0) | M16: =IF(AND(J16=1, L16>=cfg_debounce_consecutive_steps),1,0) | N16: =IF(AND(I16=1, H16=1, Raw_Data!E16<cfg_pstr_zero_threshold_kw),1,0) | O16: =IF(A16<>A15,IF(N16=1, MAX($O$5:O15)+1, 0),IF(AND(N16=1, N15=0), O15+1,IF(N16=1, O15, O15))) | P16: =IF(N16=1,COUNTIFS($A$5:$A$28,A16,$O$5:$O$28,O16,$N$5:$N$28,1),0) | Q16: =IF(AND(N16=1, P16>=cfg_debounce_consecutive_steps),1,0) | R16: =IF(AND(I16=1, H16=1, Raw_Data!F16<cfg_pstr_zero_threshold_kw),1,0) | S16: =IF(A16<>A15,IF(R16=1, MAX($S$5:S15)+1, 0),IF(AND(R16=1, R15=0), S15+1,IF(R16=1, S15, S15))) | T16: =IF(R16=1,COUNTIFS($A$5:$A$28,A16,$S$5:$S$28,S16,$R$5:$R$28,1),0) | U16: =IF(AND(R16=1, T16>=cfg_debounce_consecutive_steps),1,0) | V16: =IF(AND(I16=1, H16=1, Raw_Data!G16<cfg_pstr_zero_threshold_kw),1,0) | W16: =IF(A16<>A15,IF(V16=1, MAX($W$5:W15)+1, 0),IF(AND(V16=1, V15=0), W15+1,IF(V16=1, W15, W15))) | X16: =IF(V16=1,COUNTIFS($A$5:$A$28,A16,$W$5:$W$28,W16,$V$5:$V$28,1),0) | Y16: =IF(AND(V16=1, X16>=cfg_debounce_consecutive_steps),1,0) | Z16: =IF(AND(I16=1, H16=1, Raw_Data!H16<cfg_pstr_zero_threshold_kw),1,0) | AA16: =IF(A16<>A15,IF(Z16=1, MAX($AA$5:AA15)+1, 0),IF(AND(Z16=1, Z15=0), AA15+1,IF(Z16=1, AA15, AA15))) | AB16: =IF(Z16=1,COUNTIFS($A$5:$A$28,A16,$AA$5:$AA$28,AA16,$Z$5:$Z$28,1),0) | AC16: =IF(AND(Z16=1, AB16>=cfg_debounce_consecutive_steps),1,0)
A17: =Raw_Data!A17 | B17: =Raw_Data!B17 | C17: =Raw_Data!C17 | D17: =IF(ISNUMBER(SEARCH("shutdown",LOWER(C17)))+ISNUMBER(SEARCH("fault",LOWER(C17))),"DOWN",IF(ISNUMBER(SEARCH("grid connected",LOWER(C17)))+ISNUMBER(SEARCH("on-grid",LOWER(C17))),"ON",IF(ISNUMBER(SEARCH("standby",LOWER(C17)))+ISNUMBER(SEARCH("no sunlight",LOWER(C17))),"TRANSITIONAL","UNKNOWN"))) | E17: =MEDIAN(Raw_Data!D17:H17) | F17: =COUNTIF(Raw_Data!D17:H17, ">"&cfg_pstr_zero_threshold_kw) | G17: =100*F17/cfg_n_pv_total_in_workbook | H17: =IF(AND(E17>=cfg_sibling_median_active_kw, G17>=cfg_min_active_siblings_pct),1,0) | I17: =IF(D17="ON",1,0) | J17: =IF(AND(I17=1, H17=1, Raw_Data!D17<cfg_pstr_zero_threshold_kw),1,0) | K17: =IF(A17<>A16,IF(J17=1, MAX($K$5:K16)+1, 0),IF(AND(J17=1, J16=0), K16+1,IF(J17=1, K16, K16))) | L17: =IF(J17=1,COUNTIFS($A$5:$A$28,A17,$K$5:$K$28,K17,$J$5:$J$28,1),0) | M17: =IF(AND(J17=1, L17>=cfg_debounce_consecutive_steps),1,0) | N17: =IF(AND(I17=1, H17=1, Raw_Data!E17<cfg_pstr_zero_threshold_kw),1,0) | O17: =IF(A17<>A16,IF(N17=1, MAX($O$5:O16)+1, 0),IF(AND(N17=1, N16=0), O16+1,IF(N17=1, O16, O16))) | P17: =IF(N17=1,COUNTIFS($A$5:$A$28,A17,$O$5:$O$28,O17,$N$5:$N$28,1),0) | Q17: =IF(AND(N17=1, P17>=cfg_debounce_consecutive_steps),1,0) | R17: =IF(AND(I17=1, H17=1, Raw_Data!F17<cfg_pstr_zero_threshold_kw),1,0) | S17: =IF(A17<>A16,IF(R17=1, MAX($S$5:S16)+1, 0),IF(AND(R17=1, R16=0), S16+1,IF(R17=1, S16, S16))) | T17: =IF(R17=1,COUNTIFS($A$5:$A$28,A17,$S$5:$S$28,S17,$R$5:$R$28,1),0) | U17: =IF(AND(R17=1, T17>=cfg_debounce_consecutive_steps),1,0) | V17: =IF(AND(I17=1, H17=1, Raw_Data!G17<cfg_pstr_zero_threshold_kw),1,0) | W17: =IF(A17<>A16,IF(V17=1, MAX($W$5:W16)+1, 0),IF(AND(V17=1, V16=0), W16+1,IF(V17=1, W16, W16))) | X17: =IF(V17=1,COUNTIFS($A$5:$A$28,A17,$W$5:$W$28,W17,$V$5:$V$28,1),0) | Y17: =IF(AND(V17=1, X17>=cfg_debounce_consecutive_steps),1,0) | Z17: =IF(AND(I17=1, H17=1, Raw_Data!H17<cfg_pstr_zero_threshold_kw),1,0) | AA17: =IF(A17<>A16,IF(Z17=1, MAX($AA$5:AA16)+1, 0),IF(AND(Z17=1, Z16=0), AA16+1,IF(Z17=1, AA16, AA16))) | AB17: =IF(Z17=1,COUNTIFS($A$5:$A$28,A17,$AA$5:$AA$28,AA17,$Z$5:$Z$28,1),0) | AC17: =IF(AND(Z17=1, AB17>=cfg_debounce_consecutive_steps),1,0)
... A28: =Raw_Data!A28 | B28: =Raw_Data!B28 | C28: =Raw_Data!C28 | D28: =IF(ISNUMBER(SEARCH("shutdown",LOWER(C28)))+ISNUMBER(SEARCH("fault",LOWER(C28))),"DOWN",IF(ISNUMBER(SEARCH("grid connected",LOWER(C28)))+ISNUMBER(SEARCH("on-grid",LOWER(C28))),"ON",IF(ISNUMBER(SEARCH("standby",LOWER(C28)))+ISNUMBER(SEARCH("no sunlight",LOWER(C28))),"TRANSITIONAL","UNKNOWN"))) | E28: =MEDIAN(Raw_Data!D28:H28) | F28: =COUNTIF(Raw_Data!D28:H28, ">"&cfg_pstr_zero_threshold_kw) | G28: =100*F28/cfg_n_pv_total_in_workbook | H28: =IF(AND(E28>=cfg_sibling_median_active_kw, G28>=cfg_min_active_siblings_pct),1,0) | I28: =IF(D28="ON",1,0) | J28: =IF(AND(I28=1, H28=1, Raw_Data!D28<cfg_pstr_zero_threshold_kw),1,0) | K28: =IF(A28<>A27,IF(J28=1, MAX($K$5:K27)+1, 0),IF(AND(J28=1, J27=0), K27+1,IF(J28=1, K27, K27))) | L28: =IF(J28=1,COUNTIFS($A$5:$A$28,A28,$K$5:$K$28,K28,$J$5:$J$28,1),0) | M28: =IF(AND(J28=1, L28>=cfg_debounce_consecutive_steps),1,0) | N28: =IF(AND(I28=1, H28=1, Raw_Data!E28<cfg_pstr_zero_threshold_kw),1,0) | O28: =IF(A28<>A27,IF(N28=1, MAX($O$5:O27)+1, 0),IF(AND(N28=1, N27=0), O27+1,IF(N28=1, O27, O27))) | P28: =IF(N28=1,COUNTIFS($A$5:$A$28,A28,$O$5:$O$28,O28,$N$5:$N$28,1),0) | Q28: =IF(AND(N28=1, P28>=cfg_debounce_consecutive_steps),1,0) | R28: =IF(AND(I28=1, H28=1, Raw_Data!F28<cfg_pstr_zero_threshold_kw),1,0) | S28: =IF(A28<>A27,IF(R28=1, MAX($S$5:S27)+1, 0),IF(AND(R28=1, R27=0), S27+1,IF(R28=1, S27, S27))) | T28: =IF(R28=1,COUNTIFS($A$5:$A$28,A28,$S$5:$S$28,S28,$R$5:$R$28,1),0) | U28: =IF(AND(R28=1, T28>=cfg_debounce_consecutive_steps),1,0) | V28: =IF(AND(I28=1, H28=1, Raw_Data!G28<cfg_pstr_zero_threshold_kw),1,0) | W28: =IF(A28<>A27,IF(V28=1, MAX($W$5:W27)+1, 0),IF(AND(V28=1, V27=0), W27+1,IF(V28=1, W27, W27))) | X28: =IF(V28=1,COUNTIFS($A$5:$A$28,A28,$W$5:$W$28,W28,$V$5:$V$28,1),0) | Y28: =IF(AND(V28=1, X28>=cfg_debounce_consecutive_steps),1,0) | Z28: =IF(AND(I28=1, H28=1, Raw_Data!H28<cfg_pstr_zero_threshold_kw),1,0) | AA28: =IF(A28<>A27,IF(Z28=1, MAX($AA$5:AA27)+1, 0),IF(AND(Z28=1, Z27=0), AA27+1,IF(Z28=1, AA27, AA27))) | AB28: =IF(Z28=1,COUNTIFS($A$5:$A$28,A28,$AA$5:$AA$28,AA28,$Z$5:$Z$28,1),0) | AC28: =IF(AND(Z28=1, AB28>=cfg_debounce_consecutive_steps),1,0)

Sheet M2e_Availability
A1: M2e Availability — output finding per inverter & per string
A2: Section A: per-inverter uptime%. Section B: per-string proxy down. Severity di-derive dari uptime_pct vs threshold di Config.
A4: A. Per-inverter daily uptime
A5: Inverter_ID | B5: n_on | C5: n_down | D5: denom | E5: uptime_pct | F5: downtime_min | G5: severity | H5: threshold_breached | I5: message
A6: WB02-INV01 | B6: =COUNTIFS(Helpers_M2e!$A$5:$A$28, A6, Helpers_M2e!$D$5:$D$28, "ON") | C6: =COUNTIFS(Helpers_M2e!$A$5:$A$28, A6, Helpers_M2e!$D$5:$D$28, "DOWN") | D6: =B6+C6 | E6: =IF(D6=0, NA(), 100*B6/D6) | F6: =C6*cfg_interval_minutes | G6: =IF(ISNA(E6),"NO_DATA",IF(E6<cfg_critical_below,"CRITICAL",IF(E6<cfg_high_below,"HIGH",IF(E6<cfg_medium_below,"MEDIUM",IF(E6<cfg_info_below,"INFO","NORMAL"))))) | H6: =IF(ISNA(E6),"",IF(E6<cfg_critical_below,cfg_critical_below,IF(E6<cfg_high_below,cfg_high_below,IF(E6<cfg_medium_below,cfg_medium_below,IF(E6<cfg_info_below,cfg_info_below,cfg_info_below))))) | I6: ="inverter uptime "&TEXT(E6,"0.00")&"% (n_on="&B6&", n_down="&C6&")"
A7: WB02-INV02 | B7: =COUNTIFS(Helpers_M2e!$A$5:$A$28, A7, Helpers_M2e!$D$5:$D$28, "ON") | C7: =COUNTIFS(Helpers_M2e!$A$5:$A$28, A7, Helpers_M2e!$D$5:$D$28, "DOWN") | D7: =B7+C7 | E7: =IF(D7=0, NA(), 100*B7/D7) | F7: =C7*cfg_interval_minutes | G7: =IF(ISNA(E7),"NO_DATA",IF(E7<cfg_critical_below,"CRITICAL",IF(E7<cfg_high_below,"HIGH",IF(E7<cfg_medium_below,"MEDIUM",IF(E7<cfg_info_below,"INFO","NORMAL"))))) | H7: =IF(ISNA(E7),"",IF(E7<cfg_critical_below,cfg_critical_below,IF(E7<cfg_high_below,cfg_high_below,IF(E7<cfg_medium_below,cfg_medium_below,IF(E7<cfg_info_below,cfg_info_below,cfg_info_below))))) | I7: ="inverter uptime "&TEXT(E7,"0.00")&"% (n_on="&B7&", n_down="&C7&")"
A11: B. Per-string proxy down (event_minutes_total + uptime_pct + severity)
A12: Inverter_ID | B12: PV_string | C12: daylight_minutes_inv | D12: event_minutes | E12: n_events | F12: string_uptime_pct | G12: severity | H12: is_empty | I12: message
A13: WB02-INV01 | B13: PV1 | C13: =COUNTIFS(Helpers_M2e!$A$5:$A$28, A13, Helpers_M2e!$I$5:$I$28, 1) * cfg_interval_minutes | D13: =COUNTIFS(Helpers_M2e!$A$5:$A$28, A13, Helpers_M2e!$M$5:$M$28, 1) * cfg_interval_minutes | E13: =SUMPRODUCT((Helpers_M2e!$A$5:$A$28=A13)*(Helpers_M2e!$M$5:$M$28=1)*((Helpers_M2e!$M$4:$M$27=0)+(Helpers_M2e!$A$5:$A$28<>Helpers_M2e!$A$4:$A$27)>=1)) | F13: =IF(C13=0, NA(), MAX(0, 100 - 100*D13/C13)) | G13: =IF(H13=1,"EMPTY",IF(C13=0,"NO_DAYLIGHT",IF(F13<cfg_critical_below,"CRITICAL",IF(F13<cfg_high_below,"HIGH",IF(F13<cfg_medium_below,"MEDIUM",IF(F13<cfg_info_below,"INFO","NORMAL")))))) | H13: =IFERROR(IF(ISNUMBER(SEARCH(","&1&",", ","&VLOOKUP(A13, EmptyPVMap!$A$5:$B$8, 2, FALSE)&",")), 1, 0), 0) | I13: =IF(H13=1, "EMPTY (skip)", IF(F13>=cfg_info_below, "NORMAL", A13&" "&B13&" proxy-down "&D13&"min/"&C13&"min daylight ("&TEXT(F13,"0.00")&"% uptime)"))
A14: WB02-INV01 | B14: PV2 | C14: =COUNTIFS(Helpers_M2e!$A$5:$A$28, A14, Helpers_M2e!$I$5:$I$28, 1) * cfg_interval_minutes | D14: =COUNTIFS(Helpers_M2e!$A$5:$A$28, A14, Helpers_M2e!$Q$5:$Q$28, 1) * cfg_interval_minutes | E14: =SUMPRODUCT((Helpers_M2e!$A$5:$A$28=A14)*(Helpers_M2e!$Q$5:$Q$28=1)*((Helpers_M2e!$Q$4:$Q$27=0)+(Helpers_M2e!$A$5:$A$28<>Helpers_M2e!$A$4:$A$27)>=1)) | F14: =IF(C14=0, NA(), MAX(0, 100 - 100*D14/C14)) | G14: =IF(H14=1,"EMPTY",IF(C14=0,"NO_DAYLIGHT",IF(F14<cfg_critical_below,"CRITICAL",IF(F14<cfg_high_below,"HIGH",IF(F14<cfg_medium_below,"MEDIUM",IF(F14<cfg_info_below,"INFO","NORMAL")))))) | H14: =IFERROR(IF(ISNUMBER(SEARCH(","&2&",", ","&VLOOKUP(A14, EmptyPVMap!$A$5:$B$8, 2, FALSE)&",")), 1, 0), 0) | I14: =IF(H14=1, "EMPTY (skip)", IF(F14>=cfg_info_below, "NORMAL", A14&" "&B14&" proxy-down "&D14&"min/"&C14&"min daylight ("&TEXT(F14,"0.00")&"% uptime)"))
A15: WB02-INV01 | B15: PV3 | C15: =COUNTIFS(Helpers_M2e!$A$5:$A$28, A15, Helpers_M2e!$I$5:$I$28, 1) * cfg_interval_minutes | D15: =COUNTIFS(Helpers_M2e!$A$5:$A$28, A15, Helpers_M2e!$U$5:$U$28, 1) * cfg_interval_minutes | E15: =SUMPRODUCT((Helpers_M2e!$A$5:$A$28=A15)*(Helpers_M2e!$U$5:$U$28=1)*((Helpers_M2e!$U$4:$U$27=0)+(Helpers_M2e!$A$5:$A$28<>Helpers_M2e!$A$4:$A$27)>=1)) | F15: =IF(C15=0, NA(), MAX(0, 100 - 100*D15/C15)) | G15: =IF(H15=1,"EMPTY",IF(C15=0,"NO_DAYLIGHT",IF(F15<cfg_critical_below,"CRITICAL",IF(F15<cfg_high_below,"HIGH",IF(F15<cfg_medium_below,"MEDIUM",IF(F15<cfg_info_below,"INFO","NORMAL")))))) | H15: =IFERROR(IF(ISNUMBER(SEARCH(","&3&",", ","&VLOOKUP(A15, EmptyPVMap!$A$5:$B$8, 2, FALSE)&",")), 1, 0), 0) | I15: =IF(H15=1, "EMPTY (skip)", IF(F15>=cfg_info_below, "NORMAL", A15&" "&B15&" proxy-down "&D15&"min/"&C15&"min daylight ("&TEXT(F15,"0.00")&"% uptime)"))
A16: WB02-INV01 | B16: PV4 | C16: =COUNTIFS(Helpers_M2e!$A$5:$A$28, A16, Helpers_M2e!$I$5:$I$28, 1) * cfg_interval_minutes | D16: =COUNTIFS(Helpers_M2e!$A$5:$A$28, A16, Helpers_M2e!$Y$5:$Y$28, 1) * cfg_interval_minutes | E16: =SUMPRODUCT((Helpers_M2e!$A$5:$A$28=A16)*(Helpers_M2e!$Y$5:$Y$28=1)*((Helpers_M2e!$Y$4:$Y$27=0)+(Helpers_M2e!$A$5:$A$28<>Helpers_M2e!$A$4:$A$27)>=1)) | F16: =IF(C16=0, NA(), MAX(0, 100 - 100*D16/C16)) | G16: =IF(H16=1,"EMPTY",IF(C16=0,"NO_DAYLIGHT",IF(F16<cfg_critical_below,"CRITICAL",IF(F16<cfg_high_below,"HIGH",IF(F16<cfg_medium_below,"MEDIUM",IF(F16<cfg_info_below,"INFO","NORMAL")))))) | H16: =IFERROR(IF(ISNUMBER(SEARCH(","&4&",", ","&VLOOKUP(A16, EmptyPVMap!$A$5:$B$8, 2, FALSE)&",")), 1, 0), 0) | I16: =IF(H16=1, "EMPTY (skip)", IF(F16>=cfg_info_below, "NORMAL", A16&" "&B16&" proxy-down "&D16&"min/"&C16&"min daylight ("&TEXT(F16,"0.00")&"% uptime)"))
A17: WB02-INV01 | B17: PV5 | C17: =COUNTIFS(Helpers_M2e!$A$5:$A$28, A17, Helpers_M2e!$I$5:$I$28, 1) * cfg_interval_minutes | D17: =COUNTIFS(Helpers_M2e!$A$5:$A$28, A17, Helpers_M2e!$AC$5:$AC$28, 1) * cfg_interval_minutes | E17: =SUMPRODUCT((Helpers_M2e!$A$5:$A$28=A17)*(Helpers_M2e!$AC$5:$AC$28=1)*((Helpers_M2e!$AC$4:$AC$27=0)+(Helpers_M2e!$A$5:$A$28<>Helpers_M2e!$A$4:$A$27)>=1)) | F17: =IF(C17=0, NA(), MAX(0, 100 - 100*D17/C17)) | G17: =IF(H17=1,"EMPTY",IF(C17=0,"NO_DAYLIGHT",IF(F17<cfg_critical_below,"CRITICAL",IF(F17<cfg_high_below,"HIGH",IF(F17<cfg_medium_below,"MEDIUM",IF(F17<cfg_info_below,"INFO","NORMAL")))))) | H17: =IFERROR(IF(ISNUMBER(SEARCH(","&5&",", ","&VLOOKUP(A17, EmptyPVMap!$A$5:$B$8, 2, FALSE)&",")), 1, 0), 0) | I17: =IF(H17=1, "EMPTY (skip)", IF(F17>=cfg_info_below, "NORMAL", A17&" "&B17&" proxy-down "&D17&"min/"&C17&"min daylight ("&TEXT(F17,"0.00")&"% uptime)"))
A18: WB02-INV02 | B18: PV1 | C18: =COUNTIFS(Helpers_M2e!$A$5:$A$28, A18, Helpers_M2e!$I$5:$I$28, 1) * cfg_interval_minutes | D18: =COUNTIFS(Helpers_M2e!$A$5:$A$28, A18, Helpers_M2e!$M$5:$M$28, 1) * cfg_interval_minutes | E18: =SUMPRODUCT((Helpers_M2e!$A$5:$A$28=A18)*(Helpers_M2e!$M$5:$M$28=1)*((Helpers_M2e!$M$4:$M$27=0)+(Helpers_M2e!$A$5:$A$28<>Helpers_M2e!$A$4:$A$27)>=1)) | F18: =IF(C18=0, NA(), MAX(0, 100 - 100*D18/C18)) | G18: =IF(H18=1,"EMPTY",IF(C18=0,"NO_DAYLIGHT",IF(F18<cfg_critical_below,"CRITICAL",IF(F18<cfg_high_below,"HIGH",IF(F18<cfg_medium_below,"MEDIUM",IF(F18<cfg_info_below,"INFO","NORMAL")))))) | H18: =IFERROR(IF(ISNUMBER(SEARCH(","&1&",", ","&VLOOKUP(A18, EmptyPVMap!$A$5:$B$8, 2, FALSE)&",")), 1, 0), 0) | I18: =IF(H18=1, "EMPTY (skip)", IF(F18>=cfg_info_below, "NORMAL", A18&" "&B18&" proxy-down "&D18&"min/"&C18&"min daylight ("&TEXT(F18,"0.00")&"% uptime)"))
A19: WB02-INV02 | B19: PV2 | C19: =COUNTIFS(Helpers_M2e!$A$5:$A$28, A19, Helpers_M2e!$I$5:$I$28, 1) * cfg_interval_minutes | D19: =COUNTIFS(Helpers_M2e!$A$5:$A$28, A19, Helpers_M2e!$Q$5:$Q$28, 1) * cfg_interval_minutes | E19: =SUMPRODUCT((Helpers_M2e!$A$5:$A$28=A19)*(Helpers_M2e!$Q$5:$Q$28=1)*((Helpers_M2e!$Q$4:$Q$27=0)+(Helpers_M2e!$A$5:$A$28<>Helpers_M2e!$A$4:$A$27)>=1)) | F19: =IF(C19=0, NA(), MAX(0, 100 - 100*D19/C19)) | G19: =IF(H19=1,"EMPTY",IF(C19=0,"NO_DAYLIGHT",IF(F19<cfg_critical_below,"CRITICAL",IF(F19<cfg_high_below,"HIGH",IF(F19<cfg_medium_below,"MEDIUM",IF(F19<cfg_info_below,"INFO","NORMAL")))))) | H19: =IFERROR(IF(ISNUMBER(SEARCH(","&2&",", ","&VLOOKUP(A19, EmptyPVMap!$A$5:$B$8, 2, FALSE)&",")), 1, 0), 0) | I19: =IF(H19=1, "EMPTY (skip)", IF(F19>=cfg_info_below, "NORMAL", A19&" "&B19&" proxy-down "&D19&"min/"&C19&"min daylight ("&TEXT(F19,"0.00")&"% uptime)"))
A20: WB02-INV02 | B20: PV3 | C20: =COUNTIFS(Helpers_M2e!$A$5:$A$28, A20, Helpers_M2e!$I$5:$I$28, 1) * cfg_interval_minutes | D20: =COUNTIFS(Helpers_M2e!$A$5:$A$28, A20, Helpers_M2e!$U$5:$U$28, 1) * cfg_interval_minutes | E20: =SUMPRODUCT((Helpers_M2e!$A$5:$A$28=A20)*(Helpers_M2e!$U$5:$U$28=1)*((Helpers_M2e!$U$4:$U$27=0)+(Helpers_M2e!$A$5:$A$28<>Helpers_M2e!$A$4:$A$27)>=1)) | F20: =IF(C20=0, NA(), MAX(0, 100 - 100*D20/C20)) | G20: =IF(H20=1,"EMPTY",IF(C20=0,"NO_DAYLIGHT",IF(F20<cfg_critical_below,"CRITICAL",IF(F20<cfg_high_below,"HIGH",IF(F20<cfg_medium_below,"MEDIUM",IF(F20<cfg_info_below,"INFO","NORMAL")))))) | H20: =IFERROR(IF(ISNUMBER(SEARCH(","&3&",", ","&VLOOKUP(A20, EmptyPVMap!$A$5:$B$8, 2, FALSE)&",")), 1, 0), 0) | I20: =IF(H20=1, "EMPTY (skip)", IF(F20>=cfg_info_below, "NORMAL", A20&" "&B20&" proxy-down "&D20&"min/"&C20&"min daylight ("&TEXT(F20,"0.00")&"% uptime)"))
A21: WB02-INV02 | B21: PV4 | C21: =COUNTIFS(Helpers_M2e!$A$5:$A$28, A21, Helpers_M2e!$I$5:$I$28, 1) * cfg_interval_minutes | D21: =COUNTIFS(Helpers_M2e!$A$5:$A$28, A21, Helpers_M2e!$Y$5:$Y$28, 1) * cfg_interval_minutes | E21: =SUMPRODUCT((Helpers_M2e!$A$5:$A$28=A21)*(Helpers_M2e!$Y$5:$Y$28=1)*((Helpers_M2e!$Y$4:$Y$27=0)+(Helpers_M2e!$A$5:$A$28<>Helpers_M2e!$A$4:$A$27)>=1)) | F21: =IF(C21=0, NA(), MAX(0, 100 - 100*D21/C21)) | G21: =IF(H21=1,"EMPTY",IF(C21=0,"NO_DAYLIGHT",IF(F21<cfg_critical_below,"CRITICAL",IF(F21<cfg_high_below,"HIGH",IF(F21<cfg_medium_below,"MEDIUM",IF(F21<cfg_info_below,"INFO","NORMAL")))))) | H21: =IFERROR(IF(ISNUMBER(SEARCH(","&4&",", ","&VLOOKUP(A21, EmptyPVMap!$A$5:$B$8, 2, FALSE)&",")), 1, 0), 0) | I21: =IF(H21=1, "EMPTY (skip)", IF(F21>=cfg_info_below, "NORMAL", A21&" "&B21&" proxy-down "&D21&"min/"&C21&"min daylight ("&TEXT(F21,"0.00")&"% uptime)"))
A22: WB02-INV02 | B22: PV5 | C22: =COUNTIFS(Helpers_M2e!$A$5:$A$28, A22, Helpers_M2e!$I$5:$I$28, 1) * cfg_interval_minutes | D22: =COUNTIFS(Helpers_M2e!$A$5:$A$28, A22, Helpers_M2e!$AC$5:$AC$28, 1) * cfg_interval_minutes | E22: =SUMPRODUCT((Helpers_M2e!$A$5:$A$28=A22)*(Helpers_M2e!$AC$5:$AC$28=1)*((Helpers_M2e!$AC$4:$AC$27=0)+(Helpers_M2e!$A$5:$A$28<>Helpers_M2e!$A$4:$A$27)>=1)) | F22: =IF(C22=0, NA(), MAX(0, 100 - 100*D22/C22)) | G22: =IF(H22=1,"EMPTY",IF(C22=0,"NO_DAYLIGHT",IF(F22<cfg_critical_below,"CRITICAL",IF(F22<cfg_high_below,"HIGH",IF(F22<cfg_medium_below,"MEDIUM",IF(F22<cfg_info_below,"INFO","NORMAL")))))) | H22: =IFERROR(IF(ISNUMBER(SEARCH(","&5&",", ","&VLOOKUP(A22, EmptyPVMap!$A$5:$B$8, 2, FALSE)&",")), 1, 0), 0) | I22: =IF(H22=1, "EMPTY (skip)", IF(F22>=cfg_info_below, "NORMAL", A22&" "&B22&" proxy-down "&D22&"min/"&C22&"min daylight ("&TEXT(F22,"0.00")&"% uptime)"))

Sheet M2e_AllStrings
A1: M2e_AllStrings — tabel rapi per (inverter × PV string) — replika output Python
A2: Setiap baris = 1 PV slot. status ∈ {EMPTY, NO_DAYLIGHT, NORMAL, INFO, MEDIUM, HIGH, CRITICAL}. Pull dari M2e_Availability Section B.
A4: inverter_id | B4: pv_string | C4: status | D4: uptime_pct | E4: downtime_minutes | F4: event_minutes | G4: n_events | H4: daylight_minutes
A5: =M2e_Availability!A13 | B5: =M2e_Availability!B13 | C5: =M2e_Availability!G13 | D5: =IF(OR(M2e_Availability!G13="EMPTY",M2e_Availability!G13="NO_DAYLIGHT"),"",M2e_Availability!F13) | E5: =IF(OR(M2e_Availability!G13="EMPTY",M2e_Availability!G13="NO_DAYLIGHT"),"",M2e_Availability!D13) | F5: =IF(OR(M2e_Availability!G13="EMPTY",M2e_Availability!G13="NO_DAYLIGHT"),"",M2e_Availability!D13) | G5: =IF(M2e_Availability!G13="EMPTY",0,M2e_Availability!E13) | H5: =M2e_Availability!C13
A6: =M2e_Availability!A14 | B6: =M2e_Availability!B14 | C6: =M2e_Availability!G14 | D6: =IF(OR(M2e_Availability!G14="EMPTY",M2e_Availability!G14="NO_DAYLIGHT"),"",M2e_Availability!F14) | E6: =IF(OR(M2e_Availability!G14="EMPTY",M2e_Availability!G14="NO_DAYLIGHT"),"",M2e_Availability!D14) | F6: =IF(OR(M2e_Availability!G14="EMPTY",M2e_Availability!G14="NO_DAYLIGHT"),"",M2e_Availability!D14) | G6: =IF(M2e_Availability!G14="EMPTY",0,M2e_Availability!E14) | H6: =M2e_Availability!C14
A7: =M2e_Availability!A15 | B7: =M2e_Availability!B15 | C7: =M2e_Availability!G15 | D7: =IF(OR(M2e_Availability!G15="EMPTY",M2e_Availability!G15="NO_DAYLIGHT"),"",M2e_Availability!F15) | E7: =IF(OR(M2e_Availability!G15="EMPTY",M2e_Availability!G15="NO_DAYLIGHT"),"",M2e_Availability!D15) | F7: =IF(OR(M2e_Availability!G15="EMPTY",M2e_Availability!G15="NO_DAYLIGHT"),"",M2e_Availability!D15) | G7: =IF(M2e_Availability!G15="EMPTY",0,M2e_Availability!E15) | H7: =M2e_Availability!C15
A8: =M2e_Availability!A16 | B8: =M2e_Availability!B16 | C8: =M2e_Availability!G16 | D8: =IF(OR(M2e_Availability!G16="EMPTY",M2e_Availability!G16="NO_DAYLIGHT"),"",M2e_Availability!F16) | E8: =IF(OR(M2e_Availability!G16="EMPTY",M2e_Availability!G16="NO_DAYLIGHT"),"",M2e_Availability!D16) | F8: =IF(OR(M2e_Availability!G16="EMPTY",M2e_Availability!G16="NO_DAYLIGHT"),"",M2e_Availability!D16) | G8: =IF(M2e_Availability!G16="EMPTY",0,M2e_Availability!E16) | H8: =M2e_Availability!C16
A9: =M2e_Availability!A17 | B9: =M2e_Availability!B17 | C9: =M2e_Availability!G17 | D9: =IF(OR(M2e_Availability!G17="EMPTY",M2e_Availability!G17="NO_DAYLIGHT"),"",M2e_Availability!F17) | E9: =IF(OR(M2e_Availability!G17="EMPTY",M2e_Availability!G17="NO_DAYLIGHT"),"",M2e_Availability!D17) | F9: =IF(OR(M2e_Availability!G17="EMPTY",M2e_Availability!G17="NO_DAYLIGHT"),"",M2e_Availability!D17) | G9: =IF(M2e_Availability!G17="EMPTY",0,M2e_Availability!E17) | H9: =M2e_Availability!C17
A10: =M2e_Availability!A18 | B10: =M2e_Availability!B18 | C10: =M2e_Availability!G18 | D10: =IF(OR(M2e_Availability!G18="EMPTY",M2e_Availability!G18="NO_DAYLIGHT"),"",M2e_Availability!F18) | E10: =IF(OR(M2e_Availability!G18="EMPTY",M2e_Availability!G18="NO_DAYLIGHT"),"",M2e_Availability!D18) | F10: =IF(OR(M2e_Availability!G18="EMPTY",M2e_Availability!G18="NO_DAYLIGHT"),"",M2e_Availability!D18) | G10: =IF(M2e_Availability!G18="EMPTY",0,M2e_Availability!E18) | H10: =M2e_Availability!C18
A11: =M2e_Availability!A19 | B11: =M2e_Availability!B19 | C11: =M2e_Availability!G19 | D11: =IF(OR(M2e_Availability!G19="EMPTY",M2e_Availability!G19="NO_DAYLIGHT"),"",M2e_Availability!F19) | E11: =IF(OR(M2e_Availability!G19="EMPTY",M2e_Availability!G19="NO_DAYLIGHT"),"",M2e_Availability!D19) | F11: =IF(OR(M2e_Availability!G19="EMPTY",M2e_Availability!G19="NO_DAYLIGHT"),"",M2e_Availability!D19) | G11: =IF(M2e_Availability!G19="EMPTY",0,M2e_Availability!E19) | H11: =M2e_Availability!C19
A12: =M2e_Availability!A20 | B12: =M2e_Availability!B20 | C12: =M2e_Availability!G20 | D12: =IF(OR(M2e_Availability!G20="EMPTY",M2e_Availability!G20="NO_DAYLIGHT"),"",M2e_Availability!F20) | E12: =IF(OR(M2e_Availability!G20="EMPTY",M2e_Availability!G20="NO_DAYLIGHT"),"",M2e_Availability!D20) | F12: =IF(OR(M2e_Availability!G20="EMPTY",M2e_Availability!G20="NO_DAYLIGHT"),"",M2e_Availability!D20) | G12: =IF(M2e_Availability!G20="EMPTY",0,M2e_Availability!E20) | H12: =M2e_Availability!C20
A13: =M2e_Availability!A21 | B13: =M2e_Availability!B21 | C13: =M2e_Availability!G21 | D13: =IF(OR(M2e_Availability!G21="EMPTY",M2e_Availability!G21="NO_DAYLIGHT"),"",M2e_Availability!F21) | E13: =IF(OR(M2e_Availability!G21="EMPTY",M2e_Availability!G21="NO_DAYLIGHT"),"",M2e_Availability!D21) | F13: =IF(OR(M2e_Availability!G21="EMPTY",M2e_Availability!G21="NO_DAYLIGHT"),"",M2e_Availability!D21) | G13: =IF(M2e_Availability!G21="EMPTY",0,M2e_Availability!E21) | H13: =M2e_Availability!C21
A14: =M2e_Availability!A22 | B14: =M2e_Availability!B22 | C14: =M2e_Availability!G22 | D14: =IF(OR(M2e_Availability!G22="EMPTY",M2e_Availability!G22="NO_DAYLIGHT"),"",M2e_Availability!F22) | E14: =IF(OR(M2e_Availability!G22="EMPTY",M2e_Availability!G22="NO_DAYLIGHT"),"",M2e_Availability!D22) | F14: =IF(OR(M2e_Availability!G22="EMPTY",M2e_Availability!G22="NO_DAYLIGHT"),"",M2e_Availability!D22) | G14: =IF(M2e_Availability!G22="EMPTY",0,M2e_Availability!E22) | H14: =M2e_Availability!C22

Sheet Findings_Summary
A1: Findings_Summary — agregat semua finding NON-NORMAL & NON-EMPTY
A2: Saat ini hanya M2e. Akan tumbuh: M2b, M2a, IsolationForest, dst. Setiap iterasi tambah sheet detector → tambah baris di sini.
A4: Source Sheet | B4: sub_module | C4: inverter_id | D4: pv_string | E4: severity | F4: value (uptime_pct) | G4: threshold | H4: message
A5: M2e_Availability!A (inverter) | B5: M2e_inverter | C5: =M2e_Availability!A6 | E5: =M2e_Availability!G6 | F5: =M2e_Availability!E6 | G5: =M2e_Availability!H6 | H5: =M2e_Availability!I6
A6: M2e_Availability!A (inverter) | B6: M2e_inverter | C6: =M2e_Availability!A7 | E6: =M2e_Availability!G7 | F6: =M2e_Availability!E7 | G6: =M2e_Availability!H7 | H6: =M2e_Availability!I7
A7: M2e_Availability!B (string proxy) | B7: M2e_string_proxy | C7: =M2e_Availability!A13 | D7: =M2e_Availability!B13 | E7: =M2e_Availability!G13 | F7: =M2e_Availability!F13 | G7: (see Config) | H7: =M2e_Availability!I13
A8: M2e_Availability!B (string proxy) | B8: M2e_string_proxy | C8: =M2e_Availability!A14 | D8: =M2e_Availability!B14 | E8: =M2e_Availability!G14 | F8: =M2e_Availability!F14 | G8: (see Config) | H8: =M2e_Availability!I14
A9: M2e_Availability!B (string proxy) | B9: M2e_string_proxy | C9: =M2e_Availability!A15 | D9: =M2e_Availability!B15 | E9: =M2e_Availability!G15 | F9: =M2e_Availability!F15 | G9: (see Config) | H9: =M2e_Availability!I15
A10: M2e_Availability!B (string proxy) | B10: M2e_string_proxy | C10: =M2e_Availability!A16 | D10: =M2e_Availability!B16 | E10: =M2e_Availability!G16 | F10: =M2e_Availability!F16 | G10: (see Config) | H10: =M2e_Availability!I16
A11: M2e_Availability!B (string proxy) | B11: M2e_string_proxy | C11: =M2e_Availability!A17 | D11: =M2e_Availability!B17 | E11: =M2e_Availability!G17 | F11: =M2e_Availability!F17 | G11: (see Config) | H11: =M2e_Availability!I17
A12: M2e_Availability!B (string proxy) | B12: M2e_string_proxy | C12: =M2e_Availability!A18 | D12: =M2e_Availability!B18 | E12: =M2e_Availability!G18 | F12: =M2e_Availability!F18 | G12: (see Config) | H12: =M2e_Availability!I18
A13: M2e_Availability!B (string proxy) | B13: M2e_string_proxy | C13: =M2e_Availability!A19 | D13: =M2e_Availability!B19 | E13: =M2e_Availability!G19 | F13: =M2e_Availability!F19 | G13: (see Config) | H13: =M2e_Availability!I19
A14: M2e_Availability!B (string proxy) | B14: M2e_string_proxy | C14: =M2e_Availability!A20 | D14: =M2e_Availability!B20 | E14: =M2e_Availability!G20 | F14: =M2e_Availability!F20 | G14: (see Config) | H14: =M2e_Availability!I20
A15: M2e_Availability!B (string proxy) | B15: M2e_string_proxy | C15: =M2e_Availability!A21 | D15: =M2e_Availability!B21 | E15: =M2e_Availability!G21 | F15: =M2e_Availability!F21 | G15: (see Config) | H15: =M2e_Availability!I21
A16: M2e_Availability!B (string proxy) | B16: M2e_string_proxy | C16: =M2e_Availability!A22 | D16: =M2e_Availability!B22 | E16: =M2e_Availability!G22 | F16: =M2e_Availability!F22 | G16: (see Config) | H16: =M2e_Availability!I22
A17: --- M2b PeerZScore ---
A18: M2b_PeerZScore!C | B18: M2b_peer_zscore | C18: WB05-INV05 | D18: PV1 | E18: =M2b_PeerZScore!I22 | F18: =M2b_PeerZScore!D22 | G18: =cfg_z_threshold | H18: =M2b_PeerZScore!K22
A19: M2b_PeerZScore!C | B19: M2b_peer_zscore | C19: WB05-INV05 | D19: PV2 | E19: =M2b_PeerZScore!I23 | F19: =M2b_PeerZScore!D23 | G19: =cfg_z_threshold | H19: =M2b_PeerZScore!K23
A20: M2b_PeerZScore!C | B20: M2b_peer_zscore | C20: WB05-INV05 | D20: PV3 | E20: =M2b_PeerZScore!I24 | F20: =M2b_PeerZScore!D24 | G20: =cfg_z_threshold | H20: =M2b_PeerZScore!K24
A21: M2b_PeerZScore!C | B21: M2b_peer_zscore | C21: WB05-INV05 | D21: PV4 | E21: =M2b_PeerZScore!I25 | F21: =M2b_PeerZScore!D25 | G21: =cfg_z_threshold | H21: =M2b_PeerZScore!K25
A22: M2b_PeerZScore!C | B22: M2b_peer_zscore | C22: WB05-INV05 | D22: PV5 | E22: EMPTY | F22: - | G22: - | H22: -

Sheet PanelSpec
A1: PanelSpec — Jinko JKM625N 78HL4-BDV (mirror config/panel_spec.yaml)
A2: Konsumen: PanelSpec.voc_at_cell_temp + voc_string_nominal di peer_zscore.py
A4: Parameter | B4: Value | C4: Unit | D4: Notes
A5: panel_model | B5: Jinko JKM625N 78HL4-BDV | D5: Bifacial Tiger Neo dual-glass
A6: voc_stc_v | B6: 55.72 | C6: V | D6: Open-circuit voltage @ STC (1000 W/m², 25°C cell)
A7: vmp_stc_v | B7: 46.1 | C7: V | D7: Max-power voltage @ STC
A8: imp_stc_a | B8: 13.56 | C8: A | D8: Max-power current @ STC
A9: isc_stc_a | B9: 14.27 | C9: A | D9: Short-circuit current @ STC
A10: pmax_stc_w | B10: 625 | C10: W | D10: Max power @ STC
A11: voc_noct_v | B11: 52.93 | C11: V | D11: Voc @ NOCT (800 W/m², 20°C ambient)
A12: temp_coef_voc_pct_per_c | B12: -0.25 | C12: %/°C | D12: Voc decreases when Tcell rises
A13: temp_coef_pmax_pct_per_c | B13: -0.29 | C13: %/°C | D13: Pmax temperature coefficient
A14: temp_coef_isc_pct_per_c | B14: 0.045 | C14: %/°C | D14: Isc temperature coefficient (small +)
A15: t_stc_c | B15: 25 | C15: °C | D15: STC reference temperature
A16: max_system_voltage_v | B16: 1500 | C16: V | D16: IEC limit
A17: default_modules_per_string | B17: 26 | C17: modules | D17: Fallback (WB03-10)
... A20: modules_per_string_WB03_10 | B20: 26 | C20: modules | D20: PLTS-IKN WB03-10 layout
A22: voc_at_cell_temp(T_cell) — Excel formula
